EEEEEEEEEEEE
======================================================================
ERROR: test_403_forbidden (__main__.TestErrorPages)
----------------------------------------------------------------------
Traceback (most recent call last):
  File "/mnt/c/Users/bamal/Documents/Programming/flask-sandbox/virtual/lib/python3.8/site-packages/sqlalchemy/engine/base.py", line 3280, in _wrap_pool_connect
    return fn()
  File "/mnt/c/Users/bamal/Documents/Programming/flask-sandbox/virtual/lib/python3.8/site-packages/sqlalchemy/pool/base.py", line 310, in connect
    return _ConnectionFairy._checkout(self)
  File "/mnt/c/Users/bamal/Documents/Programming/flask-sandbox/virtual/lib/python3.8/site-packages/sqlalchemy/pool/base.py", line 868, in _checkout
    fairy = _ConnectionRecord.checkout(pool)
  File "/mnt/c/Users/bamal/Documents/Programming/flask-sandbox/virtual/lib/python3.8/site-packages/sqlalchemy/pool/base.py", line 476, in checkout
    rec = pool._do_get()
  File "/mnt/c/Users/bamal/Documents/Programming/flask-sandbox/virtual/lib/python3.8/site-packages/sqlalchemy/pool/impl.py", line 256, in _do_get
    return self._create_connection()
  File "/mnt/c/Users/bamal/Documents/Programming/flask-sandbox/virtual/lib/python3.8/site-packages/sqlalchemy/pool/base.py", line 256, in _create_connection
    return _ConnectionRecord(self)
  File "/mnt/c/Users/bamal/Documents/Programming/flask-sandbox/virtual/lib/python3.8/site-packages/sqlalchemy/pool/base.py", line 371, in __init__
    self.__connect()
  File "/mnt/c/Users/bamal/Documents/Programming/flask-sandbox/virtual/lib/python3.8/site-packages/sqlalchemy/pool/base.py", line 666, in __connect
    pool.logger.debug("Error on connect(): %s", e)
  File "/mnt/c/Users/bamal/Documents/Programming/flask-sandbox/virtual/lib/python3.8/site-packages/sqlalchemy/util/langhelpers.py", line 70, in __exit__
    compat.raise_(
  File "/mnt/c/Users/bamal/Documents/Programming/flask-sandbox/virtual/lib/python3.8/site-packages/sqlalchemy/util/compat.py", line 207, in raise_
    raise exception
  File "/mnt/c/Users/bamal/Documents/Programming/flask-sandbox/virtual/lib/python3.8/site-packages/sqlalchemy/pool/base.py", line 661, in __connect
    self.dbapi_connection = connection = pool._invoke_creator(self)
  File "/mnt/c/Users/bamal/Documents/Programming/flask-sandbox/virtual/lib/python3.8/site-packages/sqlalchemy/engine/create.py", line 590, in connect
    return dialect.connect(*cargs, **cparams)
  File "/mnt/c/Users/bamal/Documents/Programming/flask-sandbox/virtual/lib/python3.8/site-packages/sqlalchemy/engine/default.py", line 597, in connect
    return self.dbapi.connect(*cargs, **cparams)
sqlite3.OperationalError: unable to open database file

The above exception was the direct cause of the following exception:

Traceback (most recent call last):
  File "/mnt/c/Users/bamal/Documents/Programming/flask-sandbox/tests.py", line 35, in setUp
    db.create_all()
  File "/mnt/c/Users/bamal/Documents/Programming/flask-sandbox/virtual/lib/python3.8/site-packages/flask_sqlalchemy/__init__.py", line 1094, in create_all
    self._execute_for_all_tables(app, bind, 'create_all')
  File "/mnt/c/Users/bamal/Documents/Programming/flask-sandbox/virtual/lib/python3.8/site-packages/flask_sqlalchemy/__init__.py", line 1086, in _execute_for_all_tables
    op(bind=self.get_engine(app, bind), **extra)
  File "/mnt/c/Users/bamal/Documents/Programming/flask-sandbox/virtual/lib/python3.8/site-packages/sqlalchemy/sql/schema.py", line 4889, in create_all
    bind._run_ddl_visitor(
  File "/mnt/c/Users/bamal/Documents/Programming/flask-sandbox/virtual/lib/python3.8/site-packages/sqlalchemy/engine/base.py", line 3146, in _run_ddl_visitor
    with self.begin() as conn:
  File "/mnt/c/Users/bamal/Documents/Programming/flask-sandbox/virtual/lib/python3.8/site-packages/sqlalchemy/engine/base.py", line 3062, in begin
    conn = self.connect(close_with_result=close_with_result)
  File "/mnt/c/Users/bamal/Documents/Programming/flask-sandbox/virtual/lib/python3.8/site-packages/sqlalchemy/engine/base.py", line 3234, in connect
    return self._connection_cls(self, close_with_result=close_with_result)
  File "/mnt/c/Users/bamal/Documents/Programming/flask-sandbox/virtual/lib/python3.8/site-packages/sqlalchemy/engine/base.py", line 96, in __init__
    else engine.raw_connection()
  File "/mnt/c/Users/bamal/Documents/Programming/flask-sandbox/virtual/lib/python3.8/site-packages/sqlalchemy/engine/base.py", line 3313, in raw_connection
    return self._wrap_pool_connect(self.pool.connect, _connection)
  File "/mnt/c/Users/bamal/Documents/Programming/flask-sandbox/virtual/lib/python3.8/site-packages/sqlalchemy/engine/base.py", line 3283, in _wrap_pool_connect
    Connection._handle_dbapi_exception_noconnection(
  File "/mnt/c/Users/bamal/Documents/Programming/flask-sandbox/virtual/lib/python3.8/site-packages/sqlalchemy/engine/base.py", line 2117, in _handle_dbapi_exception_noconnection
    util.raise_(
  File "/mnt/c/Users/bamal/Documents/Programming/flask-sandbox/virtual/lib/python3.8/site-packages/sqlalchemy/util/compat.py", line 207, in raise_
    raise exception
  File "/mnt/c/Users/bamal/Documents/Programming/flask-sandbox/virtual/lib/python3.8/site-packages/sqlalchemy/engine/base.py", line 3280, in _wrap_pool_connect
    return fn()
  File "/mnt/c/Users/bamal/Documents/Programming/flask-sandbox/virtual/lib/python3.8/site-packages/sqlalchemy/pool/base.py", line 310, in connect
    return _ConnectionFairy._checkout(self)
  File "/mnt/c/Users/bamal/Documents/Programming/flask-sandbox/virtual/lib/python3.8/site-packages/sqlalchemy/pool/base.py", line 868, in _checkout
    fairy = _ConnectionRecord.checkout(pool)
  File "/mnt/c/Users/bamal/Documents/Programming/flask-sandbox/virtual/lib/python3.8/site-packages/sqlalchemy/pool/base.py", line 476, in checkout
    rec = pool._do_get()
  File "/mnt/c/Users/bamal/Documents/Programming/flask-sandbox/virtual/lib/python3.8/site-packages/sqlalchemy/pool/impl.py", line 256, in _do_get
    return self._create_connection()
  File "/mnt/c/Users/bamal/Documents/Programming/flask-sandbox/virtual/lib/python3.8/site-packages/sqlalchemy/pool/base.py", line 256, in _create_connection
    return _ConnectionRecord(self)
  File "/mnt/c/Users/bamal/Documents/Programming/flask-sandbox/virtual/lib/python3.8/site-packages/sqlalchemy/pool/base.py", line 371, in __init__
    self.__connect()
  File "/mnt/c/Users/bamal/Documents/Programming/flask-sandbox/virtual/lib/python3.8/site-packages/sqlalchemy/pool/base.py", line 666, in __connect
    pool.logger.debug("Error on connect(): %s", e)
  File "/mnt/c/Users/bamal/Documents/Programming/flask-sandbox/virtual/lib/python3.8/site-packages/sqlalchemy/util/langhelpers.py", line 70, in __exit__
    compat.raise_(
  File "/mnt/c/Users/bamal/Documents/Programming/flask-sandbox/virtual/lib/python3.8/site-packages/sqlalchemy/util/compat.py", line 207, in raise_
    raise exception
  File "/mnt/c/Users/bamal/Documents/Programming/flask-sandbox/virtual/lib/python3.8/site-packages/sqlalchemy/pool/base.py", line 661, in __connect
    self.dbapi_connection = connection = pool._invoke_creator(self)
  File "/mnt/c/Users/bamal/Documents/Programming/flask-sandbox/virtual/lib/python3.8/site-packages/sqlalchemy/engine/create.py", line 590, in connect
    return dialect.connect(*cargs, **cparams)
  File "/mnt/c/Users/bamal/Documents/Programming/flask-sandbox/virtual/lib/python3.8/site-packages/sqlalchemy/engine/default.py", line 597, in connect
    return self.dbapi.connect(*cargs, **cparams)
sqlalchemy.exc.OperationalError: (sqlite3.OperationalError) unable to open database file
(Background on this error at: https://sqlalche.me/e/14/e3q8)

======================================================================
ERROR: test_404_not_found (__main__.TestErrorPages)
----------------------------------------------------------------------
Traceback (most recent call last):
  File "/mnt/c/Users/bamal/Documents/Programming/flask-sandbox/virtual/lib/python3.8/site-packages/sqlalchemy/engine/base.py", line 3280, in _wrap_pool_connect
    return fn()
  File "/mnt/c/Users/bamal/Documents/Programming/flask-sandbox/virtual/lib/python3.8/site-packages/sqlalchemy/pool/base.py", line 310, in connect
    return _ConnectionFairy._checkout(self)
  File "/mnt/c/Users/bamal/Documents/Programming/flask-sandbox/virtual/lib/python3.8/site-packages/sqlalchemy/pool/base.py", line 868, in _checkout
    fairy = _ConnectionRecord.checkout(pool)
  File "/mnt/c/Users/bamal/Documents/Programming/flask-sandbox/virtual/lib/python3.8/site-packages/sqlalchemy/pool/base.py", line 476, in checkout
    rec = pool._do_get()
  File "/mnt/c/Users/bamal/Documents/Programming/flask-sandbox/virtual/lib/python3.8/site-packages/sqlalchemy/pool/impl.py", line 256, in _do_get
    return self._create_connection()
  File "/mnt/c/Users/bamal/Documents/Programming/flask-sandbox/virtual/lib/python3.8/site-packages/sqlalchemy/pool/base.py", line 256, in _create_connection
    return _ConnectionRecord(self)
  File "/mnt/c/Users/bamal/Documents/Programming/flask-sandbox/virtual/lib/python3.8/site-packages/sqlalchemy/pool/base.py", line 371, in __init__
    self.__connect()
  File "/mnt/c/Users/bamal/Documents/Programming/flask-sandbox/virtual/lib/python3.8/site-packages/sqlalchemy/pool/base.py", line 666, in __connect
    pool.logger.debug("Error on connect(): %s", e)
  File "/mnt/c/Users/bamal/Documents/Programming/flask-sandbox/virtual/lib/python3.8/site-packages/sqlalchemy/util/langhelpers.py", line 70, in __exit__
    compat.raise_(
  File "/mnt/c/Users/bamal/Documents/Programming/flask-sandbox/virtual/lib/python3.8/site-packages/sqlalchemy/util/compat.py", line 207, in raise_
    raise exception
  File "/mnt/c/Users/bamal/Documents/Programming/flask-sandbox/virtual/lib/python3.8/site-packages/sqlalchemy/pool/base.py", line 661, in __connect
    self.dbapi_connection = connection = pool._invoke_creator(self)
  File "/mnt/c/Users/bamal/Documents/Programming/flask-sandbox/virtual/lib/python3.8/site-packages/sqlalchemy/engine/create.py", line 590, in connect
    return dialect.connect(*cargs, **cparams)
  File "/mnt/c/Users/bamal/Documents/Programming/flask-sandbox/virtual/lib/python3.8/site-packages/sqlalchemy/engine/default.py", line 597, in connect
    return self.dbapi.connect(*cargs, **cparams)
sqlite3.OperationalError: unable to open database file

The above exception was the direct cause of the following exception:

Traceback (most recent call last):
  File "/mnt/c/Users/bamal/Documents/Programming/flask-sandbox/tests.py", line 35, in setUp
    db.create_all()
  File "/mnt/c/Users/bamal/Documents/Programming/flask-sandbox/virtual/lib/python3.8/site-packages/flask_sqlalchemy/__init__.py", line 1094, in create_all
    self._execute_for_all_tables(app, bind, 'create_all')
  File "/mnt/c/Users/bamal/Documents/Programming/flask-sandbox/virtual/lib/python3.8/site-packages/flask_sqlalchemy/__init__.py", line 1086, in _execute_for_all_tables
    op(bind=self.get_engine(app, bind), **extra)
  File "/mnt/c/Users/bamal/Documents/Programming/flask-sandbox/virtual/lib/python3.8/site-packages/sqlalchemy/sql/schema.py", line 4889, in create_all
    bind._run_ddl_visitor(
  File "/mnt/c/Users/bamal/Documents/Programming/flask-sandbox/virtual/lib/python3.8/site-packages/sqlalchemy/engine/base.py", line 3146, in _run_ddl_visitor
    with self.begin() as conn:
  File "/mnt/c/Users/bamal/Documents/Programming/flask-sandbox/virtual/lib/python3.8/site-packages/sqlalchemy/engine/base.py", line 3062, in begin
    conn = self.connect(close_with_result=close_with_result)
  File "/mnt/c/Users/bamal/Documents/Programming/flask-sandbox/virtual/lib/python3.8/site-packages/sqlalchemy/engine/base.py", line 3234, in connect
    return self._connection_cls(self, close_with_result=close_with_result)
  File "/mnt/c/Users/bamal/Documents/Programming/flask-sandbox/virtual/lib/python3.8/site-packages/sqlalchemy/engine/base.py", line 96, in __init__
    else engine.raw_connection()
  File "/mnt/c/Users/bamal/Documents/Programming/flask-sandbox/virtual/lib/python3.8/site-packages/sqlalchemy/engine/base.py", line 3313, in raw_connection
    return self._wrap_pool_connect(self.pool.connect, _connection)
  File "/mnt/c/Users/bamal/Documents/Programming/flask-sandbox/virtual/lib/python3.8/site-packages/sqlalchemy/engine/base.py", line 3283, in _wrap_pool_connect
    Connection._handle_dbapi_exception_noconnection(
  File "/mnt/c/Users/bamal/Documents/Programming/flask-sandbox/virtual/lib/python3.8/site-packages/sqlalchemy/engine/base.py", line 2117, in _handle_dbapi_exception_noconnection
    util.raise_(
  File "/mnt/c/Users/bamal/Documents/Programming/flask-sandbox/virtual/lib/python3.8/site-packages/sqlalchemy/util/compat.py", line 207, in raise_
    raise exception
  File "/mnt/c/Users/bamal/Documents/Programming/flask-sandbox/virtual/lib/python3.8/site-packages/sqlalchemy/engine/base.py", line 3280, in _wrap_pool_connect
    return fn()
  File "/mnt/c/Users/bamal/Documents/Programming/flask-sandbox/virtual/lib/python3.8/site-packages/sqlalchemy/pool/base.py", line 310, in connect
    return _ConnectionFairy._checkout(self)
  File "/mnt/c/Users/bamal/Documents/Programming/flask-sandbox/virtual/lib/python3.8/site-packages/sqlalchemy/pool/base.py", line 868, in _checkout
    fairy = _ConnectionRecord.checkout(pool)
  File "/mnt/c/Users/bamal/Documents/Programming/flask-sandbox/virtual/lib/python3.8/site-packages/sqlalchemy/pool/base.py", line 476, in checkout
    rec = pool._do_get()
  File "/mnt/c/Users/bamal/Documents/Programming/flask-sandbox/virtual/lib/python3.8/site-packages/sqlalchemy/pool/impl.py", line 256, in _do_get
    return self._create_connection()
  File "/mnt/c/Users/bamal/Documents/Programming/flask-sandbox/virtual/lib/python3.8/site-packages/sqlalchemy/pool/base.py", line 256, in _create_connection
    return _ConnectionRecord(self)
  File "/mnt/c/Users/bamal/Documents/Programming/flask-sandbox/virtual/lib/python3.8/site-packages/sqlalchemy/pool/base.py", line 371, in __init__
    self.__connect()
  File "/mnt/c/Users/bamal/Documents/Programming/flask-sandbox/virtual/lib/python3.8/site-packages/sqlalchemy/pool/base.py", line 666, in __connect
    pool.logger.debug("Error on connect(): %s", e)
  File "/mnt/c/Users/bamal/Documents/Programming/flask-sandbox/virtual/lib/python3.8/site-packages/sqlalchemy/util/langhelpers.py", line 70, in __exit__
    compat.raise_(
  File "/mnt/c/Users/bamal/Documents/Programming/flask-sandbox/virtual/lib/python3.8/site-packages/sqlalchemy/util/compat.py", line 207, in raise_
    raise exception
  File "/mnt/c/Users/bamal/Documents/Programming/flask-sandbox/virtual/lib/python3.8/site-packages/sqlalchemy/pool/base.py", line 661, in __connect
    self.dbapi_connection = connection = pool._invoke_creator(self)
  File "/mnt/c/Users/bamal/Documents/Programming/flask-sandbox/virtual/lib/python3.8/site-packages/sqlalchemy/engine/create.py", line 590, in connect
    return dialect.connect(*cargs, **cparams)
  File "/mnt/c/Users/bamal/Documents/Programming/flask-sandbox/virtual/lib/python3.8/site-packages/sqlalchemy/engine/default.py", line 597, in connect
    return self.dbapi.connect(*cargs, **cparams)
sqlalchemy.exc.OperationalError: (sqlite3.OperationalError) unable to open database file
(Background on this error at: https://sqlalche.me/e/14/e3q8)

======================================================================
ERROR: test_500_internal_server_error (__main__.TestErrorPages)
----------------------------------------------------------------------
Traceback (most recent call last):
  File "/mnt/c/Users/bamal/Documents/Programming/flask-sandbox/virtual/lib/python3.8/site-packages/sqlalchemy/engine/base.py", line 3280, in _wrap_pool_connect
    return fn()
  File "/mnt/c/Users/bamal/Documents/Programming/flask-sandbox/virtual/lib/python3.8/site-packages/sqlalchemy/pool/base.py", line 310, in connect
    return _ConnectionFairy._checkout(self)
  File "/mnt/c/Users/bamal/Documents/Programming/flask-sandbox/virtual/lib/python3.8/site-packages/sqlalchemy/pool/base.py", line 868, in _checkout
    fairy = _ConnectionRecord.checkout(pool)
  File "/mnt/c/Users/bamal/Documents/Programming/flask-sandbox/virtual/lib/python3.8/site-packages/sqlalchemy/pool/base.py", line 476, in checkout
    rec = pool._do_get()
  File "/mnt/c/Users/bamal/Documents/Programming/flask-sandbox/virtual/lib/python3.8/site-packages/sqlalchemy/pool/impl.py", line 256, in _do_get
    return self._create_connection()
  File "/mnt/c/Users/bamal/Documents/Programming/flask-sandbox/virtual/lib/python3.8/site-packages/sqlalchemy/pool/base.py", line 256, in _create_connection
    return _ConnectionRecord(self)
  File "/mnt/c/Users/bamal/Documents/Programming/flask-sandbox/virtual/lib/python3.8/site-packages/sqlalchemy/pool/base.py", line 371, in __init__
    self.__connect()
  File "/mnt/c/Users/bamal/Documents/Programming/flask-sandbox/virtual/lib/python3.8/site-packages/sqlalchemy/pool/base.py", line 666, in __connect
    pool.logger.debug("Error on connect(): %s", e)
  File "/mnt/c/Users/bamal/Documents/Programming/flask-sandbox/virtual/lib/python3.8/site-packages/sqlalchemy/util/langhelpers.py", line 70, in __exit__
    compat.raise_(
  File "/mnt/c/Users/bamal/Documents/Programming/flask-sandbox/virtual/lib/python3.8/site-packages/sqlalchemy/util/compat.py", line 207, in raise_
    raise exception
  File "/mnt/c/Users/bamal/Documents/Programming/flask-sandbox/virtual/lib/python3.8/site-packages/sqlalchemy/pool/base.py", line 661, in __connect
    self.dbapi_connection = connection = pool._invoke_creator(self)
  File "/mnt/c/Users/bamal/Documents/Programming/flask-sandbox/virtual/lib/python3.8/site-packages/sqlalchemy/engine/create.py", line 590, in connect
    return dialect.connect(*cargs, **cparams)
  File "/mnt/c/Users/bamal/Documents/Programming/flask-sandbox/virtual/lib/python3.8/site-packages/sqlalchemy/engine/default.py", line 597, in connect
    return self.dbapi.connect(*cargs, **cparams)
sqlite3.OperationalError: unable to open database file

The above exception was the direct cause of the following exception:

Traceback (most recent call last):
  File "/mnt/c/Users/bamal/Documents/Programming/flask-sandbox/tests.py", line 35, in setUp
    db.create_all()
  File "/mnt/c/Users/bamal/Documents/Programming/flask-sandbox/virtual/lib/python3.8/site-packages/flask_sqlalchemy/__init__.py", line 1094, in create_all
    self._execute_for_all_tables(app, bind, 'create_all')
  File "/mnt/c/Users/bamal/Documents/Programming/flask-sandbox/virtual/lib/python3.8/site-packages/flask_sqlalchemy/__init__.py", line 1086, in _execute_for_all_tables
    op(bind=self.get_engine(app, bind), **extra)
  File "/mnt/c/Users/bamal/Documents/Programming/flask-sandbox/virtual/lib/python3.8/site-packages/sqlalchemy/sql/schema.py", line 4889, in create_all
    bind._run_ddl_visitor(
  File "/mnt/c/Users/bamal/Documents/Programming/flask-sandbox/virtual/lib/python3.8/site-packages/sqlalchemy/engine/base.py", line 3146, in _run_ddl_visitor
    with self.begin() as conn:
  File "/mnt/c/Users/bamal/Documents/Programming/flask-sandbox/virtual/lib/python3.8/site-packages/sqlalchemy/engine/base.py", line 3062, in begin
    conn = self.connect(close_with_result=close_with_result)
  File "/mnt/c/Users/bamal/Documents/Programming/flask-sandbox/virtual/lib/python3.8/site-packages/sqlalchemy/engine/base.py", line 3234, in connect
    return self._connection_cls(self, close_with_result=close_with_result)
  File "/mnt/c/Users/bamal/Documents/Programming/flask-sandbox/virtual/lib/python3.8/site-packages/sqlalchemy/engine/base.py", line 96, in __init__
    else engine.raw_connection()
  File "/mnt/c/Users/bamal/Documents/Programming/flask-sandbox/virtual/lib/python3.8/site-packages/sqlalchemy/engine/base.py", line 3313, in raw_connection
    return self._wrap_pool_connect(self.pool.connect, _connection)
  File "/mnt/c/Users/bamal/Documents/Programming/flask-sandbox/virtual/lib/python3.8/site-packages/sqlalchemy/engine/base.py", line 3283, in _wrap_pool_connect
    Connection._handle_dbapi_exception_noconnection(
  File "/mnt/c/Users/bamal/Documents/Programming/flask-sandbox/virtual/lib/python3.8/site-packages/sqlalchemy/engine/base.py", line 2117, in _handle_dbapi_exception_noconnection
    util.raise_(
  File "/mnt/c/Users/bamal/Documents/Programming/flask-sandbox/virtual/lib/python3.8/site-packages/sqlalchemy/util/compat.py", line 207, in raise_
    raise exception
  File "/mnt/c/Users/bamal/Documents/Programming/flask-sandbox/virtual/lib/python3.8/site-packages/sqlalchemy/engine/base.py", line 3280, in _wrap_pool_connect
    return fn()
  File "/mnt/c/Users/bamal/Documents/Programming/flask-sandbox/virtual/lib/python3.8/site-packages/sqlalchemy/pool/base.py", line 310, in connect
    return _ConnectionFairy._checkout(self)
  File "/mnt/c/Users/bamal/Documents/Programming/flask-sandbox/virtual/lib/python3.8/site-packages/sqlalchemy/pool/base.py", line 868, in _checkout
    fairy = _ConnectionRecord.checkout(pool)
  File "/mnt/c/Users/bamal/Documents/Programming/flask-sandbox/virtual/lib/python3.8/site-packages/sqlalchemy/pool/base.py", line 476, in checkout
    rec = pool._do_get()
  File "/mnt/c/Users/bamal/Documents/Programming/flask-sandbox/virtual/lib/python3.8/site-packages/sqlalchemy/pool/impl.py", line 256, in _do_get
    return self._create_connection()
  File "/mnt/c/Users/bamal/Documents/Programming/flask-sandbox/virtual/lib/python3.8/site-packages/sqlalchemy/pool/base.py", line 256, in _create_connection
    return _ConnectionRecord(self)
  File "/mnt/c/Users/bamal/Documents/Programming/flask-sandbox/virtual/lib/python3.8/site-packages/sqlalchemy/pool/base.py", line 371, in __init__
    self.__connect()
  File "/mnt/c/Users/bamal/Documents/Programming/flask-sandbox/virtual/lib/python3.8/site-packages/sqlalchemy/pool/base.py", line 666, in __connect
    pool.logger.debug("Error on connect(): %s", e)
  File "/mnt/c/Users/bamal/Documents/Programming/flask-sandbox/virtual/lib/python3.8/site-packages/sqlalchemy/util/langhelpers.py", line 70, in __exit__
    compat.raise_(
  File "/mnt/c/Users/bamal/Documents/Programming/flask-sandbox/virtual/lib/python3.8/site-packages/sqlalchemy/util/compat.py", line 207, in raise_
    raise exception
  File "/mnt/c/Users/bamal/Documents/Programming/flask-sandbox/virtual/lib/python3.8/site-packages/sqlalchemy/pool/base.py", line 661, in __connect
    self.dbapi_connection = connection = pool._invoke_creator(self)
  File "/mnt/c/Users/bamal/Documents/Programming/flask-sandbox/virtual/lib/python3.8/site-packages/sqlalchemy/engine/create.py", line 590, in connect
    return dialect.connect(*cargs, **cparams)
  File "/mnt/c/Users/bamal/Documents/Programming/flask-sandbox/virtual/lib/python3.8/site-packages/sqlalchemy/engine/default.py", line 597, in connect
    return self.dbapi.connect(*cargs, **cparams)
sqlalchemy.exc.OperationalError: (sqlite3.OperationalError) unable to open database file
(Background on this error at: https://sqlalche.me/e/14/e3q8)

======================================================================
ERROR: test_employee_model (__main__.TestModels)
Test number of records in Employee table
----------------------------------------------------------------------
Traceback (most recent call last):
  File "/mnt/c/Users/bamal/Documents/Programming/flask-sandbox/virtual/lib/python3.8/site-packages/sqlalchemy/engine/base.py", line 3280, in _wrap_pool_connect
    return fn()
  File "/mnt/c/Users/bamal/Documents/Programming/flask-sandbox/virtual/lib/python3.8/site-packages/sqlalchemy/pool/base.py", line 310, in connect
    return _ConnectionFairy._checkout(self)
  File "/mnt/c/Users/bamal/Documents/Programming/flask-sandbox/virtual/lib/python3.8/site-packages/sqlalchemy/pool/base.py", line 868, in _checkout
    fairy = _ConnectionRecord.checkout(pool)
  File "/mnt/c/Users/bamal/Documents/Programming/flask-sandbox/virtual/lib/python3.8/site-packages/sqlalchemy/pool/base.py", line 476, in checkout
    rec = pool._do_get()
  File "/mnt/c/Users/bamal/Documents/Programming/flask-sandbox/virtual/lib/python3.8/site-packages/sqlalchemy/pool/impl.py", line 256, in _do_get
    return self._create_connection()
  File "/mnt/c/Users/bamal/Documents/Programming/flask-sandbox/virtual/lib/python3.8/site-packages/sqlalchemy/pool/base.py", line 256, in _create_connection
    return _ConnectionRecord(self)
  File "/mnt/c/Users/bamal/Documents/Programming/flask-sandbox/virtual/lib/python3.8/site-packages/sqlalchemy/pool/base.py", line 371, in __init__
    self.__connect()
  File "/mnt/c/Users/bamal/Documents/Programming/flask-sandbox/virtual/lib/python3.8/site-packages/sqlalchemy/pool/base.py", line 666, in __connect
    pool.logger.debug("Error on connect(): %s", e)
  File "/mnt/c/Users/bamal/Documents/Programming/flask-sandbox/virtual/lib/python3.8/site-packages/sqlalchemy/util/langhelpers.py", line 70, in __exit__
    compat.raise_(
  File "/mnt/c/Users/bamal/Documents/Programming/flask-sandbox/virtual/lib/python3.8/site-packages/sqlalchemy/util/compat.py", line 207, in raise_
    raise exception
  File "/mnt/c/Users/bamal/Documents/Programming/flask-sandbox/virtual/lib/python3.8/site-packages/sqlalchemy/pool/base.py", line 661, in __connect
    self.dbapi_connection = connection = pool._invoke_creator(self)
  File "/mnt/c/Users/bamal/Documents/Programming/flask-sandbox/virtual/lib/python3.8/site-packages/sqlalchemy/engine/create.py", line 590, in connect
    return dialect.connect(*cargs, **cparams)
  File "/mnt/c/Users/bamal/Documents/Programming/flask-sandbox/virtual/lib/python3.8/site-packages/sqlalchemy/engine/default.py", line 597, in connect
    return self.dbapi.connect(*cargs, **cparams)
sqlite3.OperationalError: unable to open database file

The above exception was the direct cause of the following exception:

Traceback (most recent call last):
  File "/mnt/c/Users/bamal/Documents/Programming/flask-sandbox/tests.py", line 35, in setUp
    db.create_all()
  File "/mnt/c/Users/bamal/Documents/Programming/flask-sandbox/virtual/lib/python3.8/site-packages/flask_sqlalchemy/__init__.py", line 1094, in create_all
    self._execute_for_all_tables(app, bind, 'create_all')
  File "/mnt/c/Users/bamal/Documents/Programming/flask-sandbox/virtual/lib/python3.8/site-packages/flask_sqlalchemy/__init__.py", line 1086, in _execute_for_all_tables
    op(bind=self.get_engine(app, bind), **extra)
  File "/mnt/c/Users/bamal/Documents/Programming/flask-sandbox/virtual/lib/python3.8/site-packages/sqlalchemy/sql/schema.py", line 4889, in create_all
    bind._run_ddl_visitor(
  File "/mnt/c/Users/bamal/Documents/Programming/flask-sandbox/virtual/lib/python3.8/site-packages/sqlalchemy/engine/base.py", line 3146, in _run_ddl_visitor
    with self.begin() as conn:
  File "/mnt/c/Users/bamal/Documents/Programming/flask-sandbox/virtual/lib/python3.8/site-packages/sqlalchemy/engine/base.py", line 3062, in begin
    conn = self.connect(close_with_result=close_with_result)
  File "/mnt/c/Users/bamal/Documents/Programming/flask-sandbox/virtual/lib/python3.8/site-packages/sqlalchemy/engine/base.py", line 3234, in connect
    return self._connection_cls(self, close_with_result=close_with_result)
  File "/mnt/c/Users/bamal/Documents/Programming/flask-sandbox/virtual/lib/python3.8/site-packages/sqlalchemy/engine/base.py", line 96, in __init__
    else engine.raw_connection()
  File "/mnt/c/Users/bamal/Documents/Programming/flask-sandbox/virtual/lib/python3.8/site-packages/sqlalchemy/engine/base.py", line 3313, in raw_connection
    return self._wrap_pool_connect(self.pool.connect, _connection)
  File "/mnt/c/Users/bamal/Documents/Programming/flask-sandbox/virtual/lib/python3.8/site-packages/sqlalchemy/engine/base.py", line 3283, in _wrap_pool_connect
    Connection._handle_dbapi_exception_noconnection(
  File "/mnt/c/Users/bamal/Documents/Programming/flask-sandbox/virtual/lib/python3.8/site-packages/sqlalchemy/engine/base.py", line 2117, in _handle_dbapi_exception_noconnection
    util.raise_(
  File "/mnt/c/Users/bamal/Documents/Programming/flask-sandbox/virtual/lib/python3.8/site-packages/sqlalchemy/util/compat.py", line 207, in raise_
    raise exception
  File "/mnt/c/Users/bamal/Documents/Programming/flask-sandbox/virtual/lib/python3.8/site-packages/sqlalchemy/engine/base.py", line 3280, in _wrap_pool_connect
    return fn()
  File "/mnt/c/Users/bamal/Documents/Programming/flask-sandbox/virtual/lib/python3.8/site-packages/sqlalchemy/pool/base.py", line 310, in connect
    return _ConnectionFairy._checkout(self)
  File "/mnt/c/Users/bamal/Documents/Programming/flask-sandbox/virtual/lib/python3.8/site-packages/sqlalchemy/pool/base.py", line 868, in _checkout
    fairy = _ConnectionRecord.checkout(pool)
  File "/mnt/c/Users/bamal/Documents/Programming/flask-sandbox/virtual/lib/python3.8/site-packages/sqlalchemy/pool/base.py", line 476, in checkout
    rec = pool._do_get()
  File "/mnt/c/Users/bamal/Documents/Programming/flask-sandbox/virtual/lib/python3.8/site-packages/sqlalchemy/pool/impl.py", line 256, in _do_get
    return self._create_connection()
  File "/mnt/c/Users/bamal/Documents/Programming/flask-sandbox/virtual/lib/python3.8/site-packages/sqlalchemy/pool/base.py", line 256, in _create_connection
    return _ConnectionRecord(self)
  File "/mnt/c/Users/bamal/Documents/Programming/flask-sandbox/virtual/lib/python3.8/site-packages/sqlalchemy/pool/base.py", line 371, in __init__
    self.__connect()
  File "/mnt/c/Users/bamal/Documents/Programming/flask-sandbox/virtual/lib/python3.8/site-packages/sqlalchemy/pool/base.py", line 666, in __connect
    pool.logger.debug("Error on connect(): %s", e)
  File "/mnt/c/Users/bamal/Documents/Programming/flask-sandbox/virtual/lib/python3.8/site-packages/sqlalchemy/util/langhelpers.py", line 70, in __exit__
    compat.raise_(
  File "/mnt/c/Users/bamal/Documents/Programming/flask-sandbox/virtual/lib/python3.8/site-packages/sqlalchemy/util/compat.py", line 207, in raise_
    raise exception
  File "/mnt/c/Users/bamal/Documents/Programming/flask-sandbox/virtual/lib/python3.8/site-packages/sqlalchemy/pool/base.py", line 661, in __connect
    self.dbapi_connection = connection = pool._invoke_creator(self)
  File "/mnt/c/Users/bamal/Documents/Programming/flask-sandbox/virtual/lib/python3.8/site-packages/sqlalchemy/engine/create.py", line 590, in connect
    return dialect.connect(*cargs, **cparams)
  File "/mnt/c/Users/bamal/Documents/Programming/flask-sandbox/virtual/lib/python3.8/site-packages/sqlalchemy/engine/default.py", line 597, in connect
    return self.dbapi.connect(*cargs, **cparams)
sqlalchemy.exc.OperationalError: (sqlite3.OperationalError) unable to open database file
(Background on this error at: https://sqlalche.me/e/14/e3q8)

======================================================================
ERROR: test_role_model (__main__.TestModels)
Test number of records in Role table
----------------------------------------------------------------------
Traceback (most recent call last):
  File "/mnt/c/Users/bamal/Documents/Programming/flask-sandbox/virtual/lib/python3.8/site-packages/sqlalchemy/engine/base.py", line 3280, in _wrap_pool_connect
    return fn()
  File "/mnt/c/Users/bamal/Documents/Programming/flask-sandbox/virtual/lib/python3.8/site-packages/sqlalchemy/pool/base.py", line 310, in connect
    return _ConnectionFairy._checkout(self)
  File "/mnt/c/Users/bamal/Documents/Programming/flask-sandbox/virtual/lib/python3.8/site-packages/sqlalchemy/pool/base.py", line 868, in _checkout
    fairy = _ConnectionRecord.checkout(pool)
  File "/mnt/c/Users/bamal/Documents/Programming/flask-sandbox/virtual/lib/python3.8/site-packages/sqlalchemy/pool/base.py", line 476, in checkout
    rec = pool._do_get()
  File "/mnt/c/Users/bamal/Documents/Programming/flask-sandbox/virtual/lib/python3.8/site-packages/sqlalchemy/pool/impl.py", line 256, in _do_get
    return self._create_connection()
  File "/mnt/c/Users/bamal/Documents/Programming/flask-sandbox/virtual/lib/python3.8/site-packages/sqlalchemy/pool/base.py", line 256, in _create_connection
    return _ConnectionRecord(self)
  File "/mnt/c/Users/bamal/Documents/Programming/flask-sandbox/virtual/lib/python3.8/site-packages/sqlalchemy/pool/base.py", line 371, in __init__
    self.__connect()
  File "/mnt/c/Users/bamal/Documents/Programming/flask-sandbox/virtual/lib/python3.8/site-packages/sqlalchemy/pool/base.py", line 666, in __connect
    pool.logger.debug("Error on connect(): %s", e)
  File "/mnt/c/Users/bamal/Documents/Programming/flask-sandbox/virtual/lib/python3.8/site-packages/sqlalchemy/util/langhelpers.py", line 70, in __exit__
    compat.raise_(
  File "/mnt/c/Users/bamal/Documents/Programming/flask-sandbox/virtual/lib/python3.8/site-packages/sqlalchemy/util/compat.py", line 207, in raise_
    raise exception
  File "/mnt/c/Users/bamal/Documents/Programming/flask-sandbox/virtual/lib/python3.8/site-packages/sqlalchemy/pool/base.py", line 661, in __connect
    self.dbapi_connection = connection = pool._invoke_creator(self)
  File "/mnt/c/Users/bamal/Documents/Programming/flask-sandbox/virtual/lib/python3.8/site-packages/sqlalchemy/engine/create.py", line 590, in connect
    return dialect.connect(*cargs, **cparams)
  File "/mnt/c/Users/bamal/Documents/Programming/flask-sandbox/virtual/lib/python3.8/site-packages/sqlalchemy/engine/default.py", line 597, in connect
    return self.dbapi.connect(*cargs, **cparams)
sqlite3.OperationalError: unable to open database file

The above exception was the direct cause of the following exception:

Traceback (most recent call last):
  File "/mnt/c/Users/bamal/Documents/Programming/flask-sandbox/tests.py", line 35, in setUp
    db.create_all()
  File "/mnt/c/Users/bamal/Documents/Programming/flask-sandbox/virtual/lib/python3.8/site-packages/flask_sqlalchemy/__init__.py", line 1094, in create_all
    self._execute_for_all_tables(app, bind, 'create_all')
  File "/mnt/c/Users/bamal/Documents/Programming/flask-sandbox/virtual/lib/python3.8/site-packages/flask_sqlalchemy/__init__.py", line 1086, in _execute_for_all_tables
    op(bind=self.get_engine(app, bind), **extra)
  File "/mnt/c/Users/bamal/Documents/Programming/flask-sandbox/virtual/lib/python3.8/site-packages/sqlalchemy/sql/schema.py", line 4889, in create_all
    bind._run_ddl_visitor(
  File "/mnt/c/Users/bamal/Documents/Programming/flask-sandbox/virtual/lib/python3.8/site-packages/sqlalchemy/engine/base.py", line 3146, in _run_ddl_visitor
    with self.begin() as conn:
  File "/mnt/c/Users/bamal/Documents/Programming/flask-sandbox/virtual/lib/python3.8/site-packages/sqlalchemy/engine/base.py", line 3062, in begin
    conn = self.connect(close_with_result=close_with_result)
  File "/mnt/c/Users/bamal/Documents/Programming/flask-sandbox/virtual/lib/python3.8/site-packages/sqlalchemy/engine/base.py", line 3234, in connect
    return self._connection_cls(self, close_with_result=close_with_result)
  File "/mnt/c/Users/bamal/Documents/Programming/flask-sandbox/virtual/lib/python3.8/site-packages/sqlalchemy/engine/base.py", line 96, in __init__
    else engine.raw_connection()
  File "/mnt/c/Users/bamal/Documents/Programming/flask-sandbox/virtual/lib/python3.8/site-packages/sqlalchemy/engine/base.py", line 3313, in raw_connection
    return self._wrap_pool_connect(self.pool.connect, _connection)
  File "/mnt/c/Users/bamal/Documents/Programming/flask-sandbox/virtual/lib/python3.8/site-packages/sqlalchemy/engine/base.py", line 3283, in _wrap_pool_connect
    Connection._handle_dbapi_exception_noconnection(
  File "/mnt/c/Users/bamal/Documents/Programming/flask-sandbox/virtual/lib/python3.8/site-packages/sqlalchemy/engine/base.py", line 2117, in _handle_dbapi_exception_noconnection
    util.raise_(
  File "/mnt/c/Users/bamal/Documents/Programming/flask-sandbox/virtual/lib/python3.8/site-packages/sqlalchemy/util/compat.py", line 207, in raise_
    raise exception
  File "/mnt/c/Users/bamal/Documents/Programming/flask-sandbox/virtual/lib/python3.8/site-packages/sqlalchemy/engine/base.py", line 3280, in _wrap_pool_connect
    return fn()
  File "/mnt/c/Users/bamal/Documents/Programming/flask-sandbox/virtual/lib/python3.8/site-packages/sqlalchemy/pool/base.py", line 310, in connect
    return _ConnectionFairy._checkout(self)
  File "/mnt/c/Users/bamal/Documents/Programming/flask-sandbox/virtual/lib/python3.8/site-packages/sqlalchemy/pool/base.py", line 868, in _checkout
    fairy = _ConnectionRecord.checkout(pool)
  File "/mnt/c/Users/bamal/Documents/Programming/flask-sandbox/virtual/lib/python3.8/site-packages/sqlalchemy/pool/base.py", line 476, in checkout
    rec = pool._do_get()
  File "/mnt/c/Users/bamal/Documents/Programming/flask-sandbox/virtual/lib/python3.8/site-packages/sqlalchemy/pool/impl.py", line 256, in _do_get
    return self._create_connection()
  File "/mnt/c/Users/bamal/Documents/Programming/flask-sandbox/virtual/lib/python3.8/site-packages/sqlalchemy/pool/base.py", line 256, in _create_connection
    return _ConnectionRecord(self)
  File "/mnt/c/Users/bamal/Documents/Programming/flask-sandbox/virtual/lib/python3.8/site-packages/sqlalchemy/pool/base.py", line 371, in __init__
    self.__connect()
  File "/mnt/c/Users/bamal/Documents/Programming/flask-sandbox/virtual/lib/python3.8/site-packages/sqlalchemy/pool/base.py", line 666, in __connect
    pool.logger.debug("Error on connect(): %s", e)
  File "/mnt/c/Users/bamal/Documents/Programming/flask-sandbox/virtual/lib/python3.8/site-packages/sqlalchemy/util/langhelpers.py", line 70, in __exit__
    compat.raise_(
  File "/mnt/c/Users/bamal/Documents/Programming/flask-sandbox/virtual/lib/python3.8/site-packages/sqlalchemy/util/compat.py", line 207, in raise_
    raise exception
  File "/mnt/c/Users/bamal/Documents/Programming/flask-sandbox/virtual/lib/python3.8/site-packages/sqlalchemy/pool/base.py", line 661, in __connect
    self.dbapi_connection = connection = pool._invoke_creator(self)
  File "/mnt/c/Users/bamal/Documents/Programming/flask-sandbox/virtual/lib/python3.8/site-packages/sqlalchemy/engine/create.py", line 590, in connect
    return dialect.connect(*cargs, **cparams)
  File "/mnt/c/Users/bamal/Documents/Programming/flask-sandbox/virtual/lib/python3.8/site-packages/sqlalchemy/engine/default.py", line 597, in connect
    return self.dbapi.connect(*cargs, **cparams)
sqlalchemy.exc.OperationalError: (sqlite3.OperationalError) unable to open database file
(Background on this error at: https://sqlalche.me/e/14/e3q8)

======================================================================
ERROR: test_admin_dashboard_view (__main__.TestViews)
Test that dashboard is inaccessible without login
----------------------------------------------------------------------
Traceback (most recent call last):
  File "/mnt/c/Users/bamal/Documents/Programming/flask-sandbox/virtual/lib/python3.8/site-packages/sqlalchemy/engine/base.py", line 3280, in _wrap_pool_connect
    return fn()
  File "/mnt/c/Users/bamal/Documents/Programming/flask-sandbox/virtual/lib/python3.8/site-packages/sqlalchemy/pool/base.py", line 310, in connect
    return _ConnectionFairy._checkout(self)
  File "/mnt/c/Users/bamal/Documents/Programming/flask-sandbox/virtual/lib/python3.8/site-packages/sqlalchemy/pool/base.py", line 868, in _checkout
    fairy = _ConnectionRecord.checkout(pool)
  File "/mnt/c/Users/bamal/Documents/Programming/flask-sandbox/virtual/lib/python3.8/site-packages/sqlalchemy/pool/base.py", line 476, in checkout
    rec = pool._do_get()
  File "/mnt/c/Users/bamal/Documents/Programming/flask-sandbox/virtual/lib/python3.8/site-packages/sqlalchemy/pool/impl.py", line 256, in _do_get
    return self._create_connection()
  File "/mnt/c/Users/bamal/Documents/Programming/flask-sandbox/virtual/lib/python3.8/site-packages/sqlalchemy/pool/base.py", line 256, in _create_connection
    return _ConnectionRecord(self)
  File "/mnt/c/Users/bamal/Documents/Programming/flask-sandbox/virtual/lib/python3.8/site-packages/sqlalchemy/pool/base.py", line 371, in __init__
    self.__connect()
  File "/mnt/c/Users/bamal/Documents/Programming/flask-sandbox/virtual/lib/python3.8/site-packages/sqlalchemy/pool/base.py", line 666, in __connect
    pool.logger.debug("Error on connect(): %s", e)
  File "/mnt/c/Users/bamal/Documents/Programming/flask-sandbox/virtual/lib/python3.8/site-packages/sqlalchemy/util/langhelpers.py", line 70, in __exit__
    compat.raise_(
  File "/mnt/c/Users/bamal/Documents/Programming/flask-sandbox/virtual/lib/python3.8/site-packages/sqlalchemy/util/compat.py", line 207, in raise_
    raise exception
  File "/mnt/c/Users/bamal/Documents/Programming/flask-sandbox/virtual/lib/python3.8/site-packages/sqlalchemy/pool/base.py", line 661, in __connect
    self.dbapi_connection = connection = pool._invoke_creator(self)
  File "/mnt/c/Users/bamal/Documents/Programming/flask-sandbox/virtual/lib/python3.8/site-packages/sqlalchemy/engine/create.py", line 590, in connect
    return dialect.connect(*cargs, **cparams)
  File "/mnt/c/Users/bamal/Documents/Programming/flask-sandbox/virtual/lib/python3.8/site-packages/sqlalchemy/engine/default.py", line 597, in connect
    return self.dbapi.connect(*cargs, **cparams)
sqlite3.OperationalError: unable to open database file

The above exception was the direct cause of the following exception:

Traceback (most recent call last):
  File "/mnt/c/Users/bamal/Documents/Programming/flask-sandbox/tests.py", line 35, in setUp
    db.create_all()
  File "/mnt/c/Users/bamal/Documents/Programming/flask-sandbox/virtual/lib/python3.8/site-packages/flask_sqlalchemy/__init__.py", line 1094, in create_all
    self._execute_for_all_tables(app, bind, 'create_all')
  File "/mnt/c/Users/bamal/Documents/Programming/flask-sandbox/virtual/lib/python3.8/site-packages/flask_sqlalchemy/__init__.py", line 1086, in _execute_for_all_tables
    op(bind=self.get_engine(app, bind), **extra)
  File "/mnt/c/Users/bamal/Documents/Programming/flask-sandbox/virtual/lib/python3.8/site-packages/sqlalchemy/sql/schema.py", line 4889, in create_all
    bind._run_ddl_visitor(
  File "/mnt/c/Users/bamal/Documents/Programming/flask-sandbox/virtual/lib/python3.8/site-packages/sqlalchemy/engine/base.py", line 3146, in _run_ddl_visitor
    with self.begin() as conn:
  File "/mnt/c/Users/bamal/Documents/Programming/flask-sandbox/virtual/lib/python3.8/site-packages/sqlalchemy/engine/base.py", line 3062, in begin
    conn = self.connect(close_with_result=close_with_result)
  File "/mnt/c/Users/bamal/Documents/Programming/flask-sandbox/virtual/lib/python3.8/site-packages/sqlalchemy/engine/base.py", line 3234, in connect
    return self._connection_cls(self, close_with_result=close_with_result)
  File "/mnt/c/Users/bamal/Documents/Programming/flask-sandbox/virtual/lib/python3.8/site-packages/sqlalchemy/engine/base.py", line 96, in __init__
    else engine.raw_connection()
  File "/mnt/c/Users/bamal/Documents/Programming/flask-sandbox/virtual/lib/python3.8/site-packages/sqlalchemy/engine/base.py", line 3313, in raw_connection
    return self._wrap_pool_connect(self.pool.connect, _connection)
  File "/mnt/c/Users/bamal/Documents/Programming/flask-sandbox/virtual/lib/python3.8/site-packages/sqlalchemy/engine/base.py", line 3283, in _wrap_pool_connect
    Connection._handle_dbapi_exception_noconnection(
  File "/mnt/c/Users/bamal/Documents/Programming/flask-sandbox/virtual/lib/python3.8/site-packages/sqlalchemy/engine/base.py", line 2117, in _handle_dbapi_exception_noconnection
    util.raise_(
  File "/mnt/c/Users/bamal/Documents/Programming/flask-sandbox/virtual/lib/python3.8/site-packages/sqlalchemy/util/compat.py", line 207, in raise_
    raise exception
  File "/mnt/c/Users/bamal/Documents/Programming/flask-sandbox/virtual/lib/python3.8/site-packages/sqlalchemy/engine/base.py", line 3280, in _wrap_pool_connect
    return fn()
  File "/mnt/c/Users/bamal/Documents/Programming/flask-sandbox/virtual/lib/python3.8/site-packages/sqlalchemy/pool/base.py", line 310, in connect
    return _ConnectionFairy._checkout(self)
  File "/mnt/c/Users/bamal/Documents/Programming/flask-sandbox/virtual/lib/python3.8/site-packages/sqlalchemy/pool/base.py", line 868, in _checkout
    fairy = _ConnectionRecord.checkout(pool)
  File "/mnt/c/Users/bamal/Documents/Programming/flask-sandbox/virtual/lib/python3.8/site-packages/sqlalchemy/pool/base.py", line 476, in checkout
    rec = pool._do_get()
  File "/mnt/c/Users/bamal/Documents/Programming/flask-sandbox/virtual/lib/python3.8/site-packages/sqlalchemy/pool/impl.py", line 256, in _do_get
    return self._create_connection()
  File "/mnt/c/Users/bamal/Documents/Programming/flask-sandbox/virtual/lib/python3.8/site-packages/sqlalchemy/pool/base.py", line 256, in _create_connection
    return _ConnectionRecord(self)
  File "/mnt/c/Users/bamal/Documents/Programming/flask-sandbox/virtual/lib/python3.8/site-packages/sqlalchemy/pool/base.py", line 371, in __init__
    self.__connect()
  File "/mnt/c/Users/bamal/Documents/Programming/flask-sandbox/virtual/lib/python3.8/site-packages/sqlalchemy/pool/base.py", line 666, in __connect
    pool.logger.debug("Error on connect(): %s", e)
  File "/mnt/c/Users/bamal/Documents/Programming/flask-sandbox/virtual/lib/python3.8/site-packages/sqlalchemy/util/langhelpers.py", line 70, in __exit__
    compat.raise_(
  File "/mnt/c/Users/bamal/Documents/Programming/flask-sandbox/virtual/lib/python3.8/site-packages/sqlalchemy/util/compat.py", line 207, in raise_
    raise exception
  File "/mnt/c/Users/bamal/Documents/Programming/flask-sandbox/virtual/lib/python3.8/site-packages/sqlalchemy/pool/base.py", line 661, in __connect
    self.dbapi_connection = connection = pool._invoke_creator(self)
  File "/mnt/c/Users/bamal/Documents/Programming/flask-sandbox/virtual/lib/python3.8/site-packages/sqlalchemy/engine/create.py", line 590, in connect
    return dialect.connect(*cargs, **cparams)
  File "/mnt/c/Users/bamal/Documents/Programming/flask-sandbox/virtual/lib/python3.8/site-packages/sqlalchemy/engine/default.py", line 597, in connect
    return self.dbapi.connect(*cargs, **cparams)
sqlalchemy.exc.OperationalError: (sqlite3.OperationalError) unable to open database file
(Background on this error at: https://sqlalche.me/e/14/e3q8)

======================================================================
ERROR: test_dashboard_view (__main__.TestViews)
Test that dashboard is inaccessible without login
----------------------------------------------------------------------
Traceback (most recent call last):
  File "/mnt/c/Users/bamal/Documents/Programming/flask-sandbox/virtual/lib/python3.8/site-packages/sqlalchemy/engine/base.py", line 3280, in _wrap_pool_connect
    return fn()
  File "/mnt/c/Users/bamal/Documents/Programming/flask-sandbox/virtual/lib/python3.8/site-packages/sqlalchemy/pool/base.py", line 310, in connect
    return _ConnectionFairy._checkout(self)
  File "/mnt/c/Users/bamal/Documents/Programming/flask-sandbox/virtual/lib/python3.8/site-packages/sqlalchemy/pool/base.py", line 868, in _checkout
    fairy = _ConnectionRecord.checkout(pool)
  File "/mnt/c/Users/bamal/Documents/Programming/flask-sandbox/virtual/lib/python3.8/site-packages/sqlalchemy/pool/base.py", line 476, in checkout
    rec = pool._do_get()
  File "/mnt/c/Users/bamal/Documents/Programming/flask-sandbox/virtual/lib/python3.8/site-packages/sqlalchemy/pool/impl.py", line 256, in _do_get
    return self._create_connection()
  File "/mnt/c/Users/bamal/Documents/Programming/flask-sandbox/virtual/lib/python3.8/site-packages/sqlalchemy/pool/base.py", line 256, in _create_connection
    return _ConnectionRecord(self)
  File "/mnt/c/Users/bamal/Documents/Programming/flask-sandbox/virtual/lib/python3.8/site-packages/sqlalchemy/pool/base.py", line 371, in __init__
    self.__connect()
  File "/mnt/c/Users/bamal/Documents/Programming/flask-sandbox/virtual/lib/python3.8/site-packages/sqlalchemy/pool/base.py", line 666, in __connect
    pool.logger.debug("Error on connect(): %s", e)
  File "/mnt/c/Users/bamal/Documents/Programming/flask-sandbox/virtual/lib/python3.8/site-packages/sqlalchemy/util/langhelpers.py", line 70, in __exit__
    compat.raise_(
  File "/mnt/c/Users/bamal/Documents/Programming/flask-sandbox/virtual/lib/python3.8/site-packages/sqlalchemy/util/compat.py", line 207, in raise_
    raise exception
  File "/mnt/c/Users/bamal/Documents/Programming/flask-sandbox/virtual/lib/python3.8/site-packages/sqlalchemy/pool/base.py", line 661, in __connect
    self.dbapi_connection = connection = pool._invoke_creator(self)
  File "/mnt/c/Users/bamal/Documents/Programming/flask-sandbox/virtual/lib/python3.8/site-packages/sqlalchemy/engine/create.py", line 590, in connect
    return dialect.connect(*cargs, **cparams)
  File "/mnt/c/Users/bamal/Documents/Programming/flask-sandbox/virtual/lib/python3.8/site-packages/sqlalchemy/engine/default.py", line 597, in connect
    return self.dbapi.connect(*cargs, **cparams)
sqlite3.OperationalError: unable to open database file

The above exception was the direct cause of the following exception:

Traceback (most recent call last):
  File "/mnt/c/Users/bamal/Documents/Programming/flask-sandbox/tests.py", line 35, in setUp
    db.create_all()
  File "/mnt/c/Users/bamal/Documents/Programming/flask-sandbox/virtual/lib/python3.8/site-packages/flask_sqlalchemy/__init__.py", line 1094, in create_all
    self._execute_for_all_tables(app, bind, 'create_all')
  File "/mnt/c/Users/bamal/Documents/Programming/flask-sandbox/virtual/lib/python3.8/site-packages/flask_sqlalchemy/__init__.py", line 1086, in _execute_for_all_tables
    op(bind=self.get_engine(app, bind), **extra)
  File "/mnt/c/Users/bamal/Documents/Programming/flask-sandbox/virtual/lib/python3.8/site-packages/sqlalchemy/sql/schema.py", line 4889, in create_all
    bind._run_ddl_visitor(
  File "/mnt/c/Users/bamal/Documents/Programming/flask-sandbox/virtual/lib/python3.8/site-packages/sqlalchemy/engine/base.py", line 3146, in _run_ddl_visitor
    with self.begin() as conn:
  File "/mnt/c/Users/bamal/Documents/Programming/flask-sandbox/virtual/lib/python3.8/site-packages/sqlalchemy/engine/base.py", line 3062, in begin
    conn = self.connect(close_with_result=close_with_result)
  File "/mnt/c/Users/bamal/Documents/Programming/flask-sandbox/virtual/lib/python3.8/site-packages/sqlalchemy/engine/base.py", line 3234, in connect
    return self._connection_cls(self, close_with_result=close_with_result)
  File "/mnt/c/Users/bamal/Documents/Programming/flask-sandbox/virtual/lib/python3.8/site-packages/sqlalchemy/engine/base.py", line 96, in __init__
    else engine.raw_connection()
  File "/mnt/c/Users/bamal/Documents/Programming/flask-sandbox/virtual/lib/python3.8/site-packages/sqlalchemy/engine/base.py", line 3313, in raw_connection
    return self._wrap_pool_connect(self.pool.connect, _connection)
  File "/mnt/c/Users/bamal/Documents/Programming/flask-sandbox/virtual/lib/python3.8/site-packages/sqlalchemy/engine/base.py", line 3283, in _wrap_pool_connect
    Connection._handle_dbapi_exception_noconnection(
  File "/mnt/c/Users/bamal/Documents/Programming/flask-sandbox/virtual/lib/python3.8/site-packages/sqlalchemy/engine/base.py", line 2117, in _handle_dbapi_exception_noconnection
    util.raise_(
  File "/mnt/c/Users/bamal/Documents/Programming/flask-sandbox/virtual/lib/python3.8/site-packages/sqlalchemy/util/compat.py", line 207, in raise_
    raise exception
  File "/mnt/c/Users/bamal/Documents/Programming/flask-sandbox/virtual/lib/python3.8/site-packages/sqlalchemy/engine/base.py", line 3280, in _wrap_pool_connect
    return fn()
  File "/mnt/c/Users/bamal/Documents/Programming/flask-sandbox/virtual/lib/python3.8/site-packages/sqlalchemy/pool/base.py", line 310, in connect
    return _ConnectionFairy._checkout(self)
  File "/mnt/c/Users/bamal/Documents/Programming/flask-sandbox/virtual/lib/python3.8/site-packages/sqlalchemy/pool/base.py", line 868, in _checkout
    fairy = _ConnectionRecord.checkout(pool)
  File "/mnt/c/Users/bamal/Documents/Programming/flask-sandbox/virtual/lib/python3.8/site-packages/sqlalchemy/pool/base.py", line 476, in checkout
    rec = pool._do_get()
  File "/mnt/c/Users/bamal/Documents/Programming/flask-sandbox/virtual/lib/python3.8/site-packages/sqlalchemy/pool/impl.py", line 256, in _do_get
    return self._create_connection()
  File "/mnt/c/Users/bamal/Documents/Programming/flask-sandbox/virtual/lib/python3.8/site-packages/sqlalchemy/pool/base.py", line 256, in _create_connection
    return _ConnectionRecord(self)
  File "/mnt/c/Users/bamal/Documents/Programming/flask-sandbox/virtual/lib/python3.8/site-packages/sqlalchemy/pool/base.py", line 371, in __init__
    self.__connect()
  File "/mnt/c/Users/bamal/Documents/Programming/flask-sandbox/virtual/lib/python3.8/site-packages/sqlalchemy/pool/base.py", line 666, in __connect
    pool.logger.debug("Error on connect(): %s", e)
  File "/mnt/c/Users/bamal/Documents/Programming/flask-sandbox/virtual/lib/python3.8/site-packages/sqlalchemy/util/langhelpers.py", line 70, in __exit__
    compat.raise_(
  File "/mnt/c/Users/bamal/Documents/Programming/flask-sandbox/virtual/lib/python3.8/site-packages/sqlalchemy/util/compat.py", line 207, in raise_
    raise exception
  File "/mnt/c/Users/bamal/Documents/Programming/flask-sandbox/virtual/lib/python3.8/site-packages/sqlalchemy/pool/base.py", line 661, in __connect
    self.dbapi_connection = connection = pool._invoke_creator(self)
  File "/mnt/c/Users/bamal/Documents/Programming/flask-sandbox/virtual/lib/python3.8/site-packages/sqlalchemy/engine/create.py", line 590, in connect
    return dialect.connect(*cargs, **cparams)
  File "/mnt/c/Users/bamal/Documents/Programming/flask-sandbox/virtual/lib/python3.8/site-packages/sqlalchemy/engine/default.py", line 597, in connect
    return self.dbapi.connect(*cargs, **cparams)
sqlalchemy.exc.OperationalError: (sqlite3.OperationalError) unable to open database file
(Background on this error at: https://sqlalche.me/e/14/e3q8)

======================================================================
ERROR: test_employees_view (__main__.TestViews)
Test that employees page is inaccessible without login
----------------------------------------------------------------------
Traceback (most recent call last):
  File "/mnt/c/Users/bamal/Documents/Programming/flask-sandbox/virtual/lib/python3.8/site-packages/sqlalchemy/engine/base.py", line 3280, in _wrap_pool_connect
    return fn()
  File "/mnt/c/Users/bamal/Documents/Programming/flask-sandbox/virtual/lib/python3.8/site-packages/sqlalchemy/pool/base.py", line 310, in connect
    return _ConnectionFairy._checkout(self)
  File "/mnt/c/Users/bamal/Documents/Programming/flask-sandbox/virtual/lib/python3.8/site-packages/sqlalchemy/pool/base.py", line 868, in _checkout
    fairy = _ConnectionRecord.checkout(pool)
  File "/mnt/c/Users/bamal/Documents/Programming/flask-sandbox/virtual/lib/python3.8/site-packages/sqlalchemy/pool/base.py", line 476, in checkout
    rec = pool._do_get()
  File "/mnt/c/Users/bamal/Documents/Programming/flask-sandbox/virtual/lib/python3.8/site-packages/sqlalchemy/pool/impl.py", line 256, in _do_get
    return self._create_connection()
  File "/mnt/c/Users/bamal/Documents/Programming/flask-sandbox/virtual/lib/python3.8/site-packages/sqlalchemy/pool/base.py", line 256, in _create_connection
    return _ConnectionRecord(self)
  File "/mnt/c/Users/bamal/Documents/Programming/flask-sandbox/virtual/lib/python3.8/site-packages/sqlalchemy/pool/base.py", line 371, in __init__
    self.__connect()
  File "/mnt/c/Users/bamal/Documents/Programming/flask-sandbox/virtual/lib/python3.8/site-packages/sqlalchemy/pool/base.py", line 666, in __connect
    pool.logger.debug("Error on connect(): %s", e)
  File "/mnt/c/Users/bamal/Documents/Programming/flask-sandbox/virtual/lib/python3.8/site-packages/sqlalchemy/util/langhelpers.py", line 70, in __exit__
    compat.raise_(
  File "/mnt/c/Users/bamal/Documents/Programming/flask-sandbox/virtual/lib/python3.8/site-packages/sqlalchemy/util/compat.py", line 207, in raise_
    raise exception
  File "/mnt/c/Users/bamal/Documents/Programming/flask-sandbox/virtual/lib/python3.8/site-packages/sqlalchemy/pool/base.py", line 661, in __connect
    self.dbapi_connection = connection = pool._invoke_creator(self)
  File "/mnt/c/Users/bamal/Documents/Programming/flask-sandbox/virtual/lib/python3.8/site-packages/sqlalchemy/engine/create.py", line 590, in connect
    return dialect.connect(*cargs, **cparams)
  File "/mnt/c/Users/bamal/Documents/Programming/flask-sandbox/virtual/lib/python3.8/site-packages/sqlalchemy/engine/default.py", line 597, in connect
    return self.dbapi.connect(*cargs, **cparams)
sqlite3.OperationalError: unable to open database file

The above exception was the direct cause of the following exception:

Traceback (most recent call last):
  File "/mnt/c/Users/bamal/Documents/Programming/flask-sandbox/tests.py", line 35, in setUp
    db.create_all()
  File "/mnt/c/Users/bamal/Documents/Programming/flask-sandbox/virtual/lib/python3.8/site-packages/flask_sqlalchemy/__init__.py", line 1094, in create_all
    self._execute_for_all_tables(app, bind, 'create_all')
  File "/mnt/c/Users/bamal/Documents/Programming/flask-sandbox/virtual/lib/python3.8/site-packages/flask_sqlalchemy/__init__.py", line 1086, in _execute_for_all_tables
    op(bind=self.get_engine(app, bind), **extra)
  File "/mnt/c/Users/bamal/Documents/Programming/flask-sandbox/virtual/lib/python3.8/site-packages/sqlalchemy/sql/schema.py", line 4889, in create_all
    bind._run_ddl_visitor(
  File "/mnt/c/Users/bamal/Documents/Programming/flask-sandbox/virtual/lib/python3.8/site-packages/sqlalchemy/engine/base.py", line 3146, in _run_ddl_visitor
    with self.begin() as conn:
  File "/mnt/c/Users/bamal/Documents/Programming/flask-sandbox/virtual/lib/python3.8/site-packages/sqlalchemy/engine/base.py", line 3062, in begin
    conn = self.connect(close_with_result=close_with_result)
  File "/mnt/c/Users/bamal/Documents/Programming/flask-sandbox/virtual/lib/python3.8/site-packages/sqlalchemy/engine/base.py", line 3234, in connect
    return self._connection_cls(self, close_with_result=close_with_result)
  File "/mnt/c/Users/bamal/Documents/Programming/flask-sandbox/virtual/lib/python3.8/site-packages/sqlalchemy/engine/base.py", line 96, in __init__
    else engine.raw_connection()
  File "/mnt/c/Users/bamal/Documents/Programming/flask-sandbox/virtual/lib/python3.8/site-packages/sqlalchemy/engine/base.py", line 3313, in raw_connection
    return self._wrap_pool_connect(self.pool.connect, _connection)
  File "/mnt/c/Users/bamal/Documents/Programming/flask-sandbox/virtual/lib/python3.8/site-packages/sqlalchemy/engine/base.py", line 3283, in _wrap_pool_connect
    Connection._handle_dbapi_exception_noconnection(
  File "/mnt/c/Users/bamal/Documents/Programming/flask-sandbox/virtual/lib/python3.8/site-packages/sqlalchemy/engine/base.py", line 2117, in _handle_dbapi_exception_noconnection
    util.raise_(
  File "/mnt/c/Users/bamal/Documents/Programming/flask-sandbox/virtual/lib/python3.8/site-packages/sqlalchemy/util/compat.py", line 207, in raise_
    raise exception
  File "/mnt/c/Users/bamal/Documents/Programming/flask-sandbox/virtual/lib/python3.8/site-packages/sqlalchemy/engine/base.py", line 3280, in _wrap_pool_connect
    return fn()
  File "/mnt/c/Users/bamal/Documents/Programming/flask-sandbox/virtual/lib/python3.8/site-packages/sqlalchemy/pool/base.py", line 310, in connect
    return _ConnectionFairy._checkout(self)
  File "/mnt/c/Users/bamal/Documents/Programming/flask-sandbox/virtual/lib/python3.8/site-packages/sqlalchemy/pool/base.py", line 868, in _checkout
    fairy = _ConnectionRecord.checkout(pool)
  File "/mnt/c/Users/bamal/Documents/Programming/flask-sandbox/virtual/lib/python3.8/site-packages/sqlalchemy/pool/base.py", line 476, in checkout
    rec = pool._do_get()
  File "/mnt/c/Users/bamal/Documents/Programming/flask-sandbox/virtual/lib/python3.8/site-packages/sqlalchemy/pool/impl.py", line 256, in _do_get
    return self._create_connection()
  File "/mnt/c/Users/bamal/Documents/Programming/flask-sandbox/virtual/lib/python3.8/site-packages/sqlalchemy/pool/base.py", line 256, in _create_connection
    return _ConnectionRecord(self)
  File "/mnt/c/Users/bamal/Documents/Programming/flask-sandbox/virtual/lib/python3.8/site-packages/sqlalchemy/pool/base.py", line 371, in __init__
    self.__connect()
  File "/mnt/c/Users/bamal/Documents/Programming/flask-sandbox/virtual/lib/python3.8/site-packages/sqlalchemy/pool/base.py", line 666, in __connect
    pool.logger.debug("Error on connect(): %s", e)
  File "/mnt/c/Users/bamal/Documents/Programming/flask-sandbox/virtual/lib/python3.8/site-packages/sqlalchemy/util/langhelpers.py", line 70, in __exit__
    compat.raise_(
  File "/mnt/c/Users/bamal/Documents/Programming/flask-sandbox/virtual/lib/python3.8/site-packages/sqlalchemy/util/compat.py", line 207, in raise_
    raise exception
  File "/mnt/c/Users/bamal/Documents/Programming/flask-sandbox/virtual/lib/python3.8/site-packages/sqlalchemy/pool/base.py", line 661, in __connect
    self.dbapi_connection = connection = pool._invoke_creator(self)
  File "/mnt/c/Users/bamal/Documents/Programming/flask-sandbox/virtual/lib/python3.8/site-packages/sqlalchemy/engine/create.py", line 590, in connect
    return dialect.connect(*cargs, **cparams)
  File "/mnt/c/Users/bamal/Documents/Programming/flask-sandbox/virtual/lib/python3.8/site-packages/sqlalchemy/engine/default.py", line 597, in connect
    return self.dbapi.connect(*cargs, **cparams)
sqlalchemy.exc.OperationalError: (sqlite3.OperationalError) unable to open database file
(Background on this error at: https://sqlalche.me/e/14/e3q8)

======================================================================
ERROR: test_homepage_view (__main__.TestViews)
Test that homepage is accessible without login
----------------------------------------------------------------------
Traceback (most recent call last):
  File "/mnt/c/Users/bamal/Documents/Programming/flask-sandbox/virtual/lib/python3.8/site-packages/sqlalchemy/engine/base.py", line 3280, in _wrap_pool_connect
    return fn()
  File "/mnt/c/Users/bamal/Documents/Programming/flask-sandbox/virtual/lib/python3.8/site-packages/sqlalchemy/pool/base.py", line 310, in connect
    return _ConnectionFairy._checkout(self)
  File "/mnt/c/Users/bamal/Documents/Programming/flask-sandbox/virtual/lib/python3.8/site-packages/sqlalchemy/pool/base.py", line 868, in _checkout
    fairy = _ConnectionRecord.checkout(pool)
  File "/mnt/c/Users/bamal/Documents/Programming/flask-sandbox/virtual/lib/python3.8/site-packages/sqlalchemy/pool/base.py", line 476, in checkout
    rec = pool._do_get()
  File "/mnt/c/Users/bamal/Documents/Programming/flask-sandbox/virtual/lib/python3.8/site-packages/sqlalchemy/pool/impl.py", line 256, in _do_get
    return self._create_connection()
  File "/mnt/c/Users/bamal/Documents/Programming/flask-sandbox/virtual/lib/python3.8/site-packages/sqlalchemy/pool/base.py", line 256, in _create_connection
    return _ConnectionRecord(self)
  File "/mnt/c/Users/bamal/Documents/Programming/flask-sandbox/virtual/lib/python3.8/site-packages/sqlalchemy/pool/base.py", line 371, in __init__
    self.__connect()
  File "/mnt/c/Users/bamal/Documents/Programming/flask-sandbox/virtual/lib/python3.8/site-packages/sqlalchemy/pool/base.py", line 666, in __connect
    pool.logger.debug("Error on connect(): %s", e)
  File "/mnt/c/Users/bamal/Documents/Programming/flask-sandbox/virtual/lib/python3.8/site-packages/sqlalchemy/util/langhelpers.py", line 70, in __exit__
    compat.raise_(
  File "/mnt/c/Users/bamal/Documents/Programming/flask-sandbox/virtual/lib/python3.8/site-packages/sqlalchemy/util/compat.py", line 207, in raise_
    raise exception
  File "/mnt/c/Users/bamal/Documents/Programming/flask-sandbox/virtual/lib/python3.8/site-packages/sqlalchemy/pool/base.py", line 661, in __connect
    self.dbapi_connection = connection = pool._invoke_creator(self)
  File "/mnt/c/Users/bamal/Documents/Programming/flask-sandbox/virtual/lib/python3.8/site-packages/sqlalchemy/engine/create.py", line 590, in connect
    return dialect.connect(*cargs, **cparams)
  File "/mnt/c/Users/bamal/Documents/Programming/flask-sandbox/virtual/lib/python3.8/site-packages/sqlalchemy/engine/default.py", line 597, in connect
    return self.dbapi.connect(*cargs, **cparams)
sqlite3.OperationalError: unable to open database file

The above exception was the direct cause of the following exception:

Traceback (most recent call last):
  File "/mnt/c/Users/bamal/Documents/Programming/flask-sandbox/tests.py", line 35, in setUp
    db.create_all()
  File "/mnt/c/Users/bamal/Documents/Programming/flask-sandbox/virtual/lib/python3.8/site-packages/flask_sqlalchemy/__init__.py", line 1094, in create_all
    self._execute_for_all_tables(app, bind, 'create_all')
  File "/mnt/c/Users/bamal/Documents/Programming/flask-sandbox/virtual/lib/python3.8/site-packages/flask_sqlalchemy/__init__.py", line 1086, in _execute_for_all_tables
    op(bind=self.get_engine(app, bind), **extra)
  File "/mnt/c/Users/bamal/Documents/Programming/flask-sandbox/virtual/lib/python3.8/site-packages/sqlalchemy/sql/schema.py", line 4889, in create_all
    bind._run_ddl_visitor(
  File "/mnt/c/Users/bamal/Documents/Programming/flask-sandbox/virtual/lib/python3.8/site-packages/sqlalchemy/engine/base.py", line 3146, in _run_ddl_visitor
    with self.begin() as conn:
  File "/mnt/c/Users/bamal/Documents/Programming/flask-sandbox/virtual/lib/python3.8/site-packages/sqlalchemy/engine/base.py", line 3062, in begin
    conn = self.connect(close_with_result=close_with_result)
  File "/mnt/c/Users/bamal/Documents/Programming/flask-sandbox/virtual/lib/python3.8/site-packages/sqlalchemy/engine/base.py", line 3234, in connect
    return self._connection_cls(self, close_with_result=close_with_result)
  File "/mnt/c/Users/bamal/Documents/Programming/flask-sandbox/virtual/lib/python3.8/site-packages/sqlalchemy/engine/base.py", line 96, in __init__
    else engine.raw_connection()
  File "/mnt/c/Users/bamal/Documents/Programming/flask-sandbox/virtual/lib/python3.8/site-packages/sqlalchemy/engine/base.py", line 3313, in raw_connection
    return self._wrap_pool_connect(self.pool.connect, _connection)
  File "/mnt/c/Users/bamal/Documents/Programming/flask-sandbox/virtual/lib/python3.8/site-packages/sqlalchemy/engine/base.py", line 3283, in _wrap_pool_connect
    Connection._handle_dbapi_exception_noconnection(
  File "/mnt/c/Users/bamal/Documents/Programming/flask-sandbox/virtual/lib/python3.8/site-packages/sqlalchemy/engine/base.py", line 2117, in _handle_dbapi_exception_noconnection
    util.raise_(
  File "/mnt/c/Users/bamal/Documents/Programming/flask-sandbox/virtual/lib/python3.8/site-packages/sqlalchemy/util/compat.py", line 207, in raise_
    raise exception
  File "/mnt/c/Users/bamal/Documents/Programming/flask-sandbox/virtual/lib/python3.8/site-packages/sqlalchemy/engine/base.py", line 3280, in _wrap_pool_connect
    return fn()
  File "/mnt/c/Users/bamal/Documents/Programming/flask-sandbox/virtual/lib/python3.8/site-packages/sqlalchemy/pool/base.py", line 310, in connect
    return _ConnectionFairy._checkout(self)
  File "/mnt/c/Users/bamal/Documents/Programming/flask-sandbox/virtual/lib/python3.8/site-packages/sqlalchemy/pool/base.py", line 868, in _checkout
    fairy = _ConnectionRecord.checkout(pool)
  File "/mnt/c/Users/bamal/Documents/Programming/flask-sandbox/virtual/lib/python3.8/site-packages/sqlalchemy/pool/base.py", line 476, in checkout
    rec = pool._do_get()
  File "/mnt/c/Users/bamal/Documents/Programming/flask-sandbox/virtual/lib/python3.8/site-packages/sqlalchemy/pool/impl.py", line 256, in _do_get
    return self._create_connection()
  File "/mnt/c/Users/bamal/Documents/Programming/flask-sandbox/virtual/lib/python3.8/site-packages/sqlalchemy/pool/base.py", line 256, in _create_connection
    return _ConnectionRecord(self)
  File "/mnt/c/Users/bamal/Documents/Programming/flask-sandbox/virtual/lib/python3.8/site-packages/sqlalchemy/pool/base.py", line 371, in __init__
    self.__connect()
  File "/mnt/c/Users/bamal/Documents/Programming/flask-sandbox/virtual/lib/python3.8/site-packages/sqlalchemy/pool/base.py", line 666, in __connect
    pool.logger.debug("Error on connect(): %s", e)
  File "/mnt/c/Users/bamal/Documents/Programming/flask-sandbox/virtual/lib/python3.8/site-packages/sqlalchemy/util/langhelpers.py", line 70, in __exit__
    compat.raise_(
  File "/mnt/c/Users/bamal/Documents/Programming/flask-sandbox/virtual/lib/python3.8/site-packages/sqlalchemy/util/compat.py", line 207, in raise_
    raise exception
  File "/mnt/c/Users/bamal/Documents/Programming/flask-sandbox/virtual/lib/python3.8/site-packages/sqlalchemy/pool/base.py", line 661, in __connect
    self.dbapi_connection = connection = pool._invoke_creator(self)
  File "/mnt/c/Users/bamal/Documents/Programming/flask-sandbox/virtual/lib/python3.8/site-packages/sqlalchemy/engine/create.py", line 590, in connect
    return dialect.connect(*cargs, **cparams)
  File "/mnt/c/Users/bamal/Documents/Programming/flask-sandbox/virtual/lib/python3.8/site-packages/sqlalchemy/engine/default.py", line 597, in connect
    return self.dbapi.connect(*cargs, **cparams)
sqlalchemy.exc.OperationalError: (sqlite3.OperationalError) unable to open database file
(Background on this error at: https://sqlalche.me/e/14/e3q8)

======================================================================
ERROR: test_login_view (__main__.TestViews)
Test that login page is accessible without login
----------------------------------------------------------------------
Traceback (most recent call last):
  File "/mnt/c/Users/bamal/Documents/Programming/flask-sandbox/virtual/lib/python3.8/site-packages/sqlalchemy/engine/base.py", line 3280, in _wrap_pool_connect
    return fn()
  File "/mnt/c/Users/bamal/Documents/Programming/flask-sandbox/virtual/lib/python3.8/site-packages/sqlalchemy/pool/base.py", line 310, in connect
    return _ConnectionFairy._checkout(self)
  File "/mnt/c/Users/bamal/Documents/Programming/flask-sandbox/virtual/lib/python3.8/site-packages/sqlalchemy/pool/base.py", line 868, in _checkout
    fairy = _ConnectionRecord.checkout(pool)
  File "/mnt/c/Users/bamal/Documents/Programming/flask-sandbox/virtual/lib/python3.8/site-packages/sqlalchemy/pool/base.py", line 476, in checkout
    rec = pool._do_get()
  File "/mnt/c/Users/bamal/Documents/Programming/flask-sandbox/virtual/lib/python3.8/site-packages/sqlalchemy/pool/impl.py", line 256, in _do_get
    return self._create_connection()
  File "/mnt/c/Users/bamal/Documents/Programming/flask-sandbox/virtual/lib/python3.8/site-packages/sqlalchemy/pool/base.py", line 256, in _create_connection
    return _ConnectionRecord(self)
  File "/mnt/c/Users/bamal/Documents/Programming/flask-sandbox/virtual/lib/python3.8/site-packages/sqlalchemy/pool/base.py", line 371, in __init__
    self.__connect()
  File "/mnt/c/Users/bamal/Documents/Programming/flask-sandbox/virtual/lib/python3.8/site-packages/sqlalchemy/pool/base.py", line 666, in __connect
    pool.logger.debug("Error on connect(): %s", e)
  File "/mnt/c/Users/bamal/Documents/Programming/flask-sandbox/virtual/lib/python3.8/site-packages/sqlalchemy/util/langhelpers.py", line 70, in __exit__
    compat.raise_(
  File "/mnt/c/Users/bamal/Documents/Programming/flask-sandbox/virtual/lib/python3.8/site-packages/sqlalchemy/util/compat.py", line 207, in raise_
    raise exception
  File "/mnt/c/Users/bamal/Documents/Programming/flask-sandbox/virtual/lib/python3.8/site-packages/sqlalchemy/pool/base.py", line 661, in __connect
    self.dbapi_connection = connection = pool._invoke_creator(self)
  File "/mnt/c/Users/bamal/Documents/Programming/flask-sandbox/virtual/lib/python3.8/site-packages/sqlalchemy/engine/create.py", line 590, in connect
    return dialect.connect(*cargs, **cparams)
  File "/mnt/c/Users/bamal/Documents/Programming/flask-sandbox/virtual/lib/python3.8/site-packages/sqlalchemy/engine/default.py", line 597, in connect
    return self.dbapi.connect(*cargs, **cparams)
sqlite3.OperationalError: unable to open database file

The above exception was the direct cause of the following exception:

Traceback (most recent call last):
  File "/mnt/c/Users/bamal/Documents/Programming/flask-sandbox/tests.py", line 35, in setUp
    db.create_all()
  File "/mnt/c/Users/bamal/Documents/Programming/flask-sandbox/virtual/lib/python3.8/site-packages/flask_sqlalchemy/__init__.py", line 1094, in create_all
    self._execute_for_all_tables(app, bind, 'create_all')
  File "/mnt/c/Users/bamal/Documents/Programming/flask-sandbox/virtual/lib/python3.8/site-packages/flask_sqlalchemy/__init__.py", line 1086, in _execute_for_all_tables
    op(bind=self.get_engine(app, bind), **extra)
  File "/mnt/c/Users/bamal/Documents/Programming/flask-sandbox/virtual/lib/python3.8/site-packages/sqlalchemy/sql/schema.py", line 4889, in create_all
    bind._run_ddl_visitor(
  File "/mnt/c/Users/bamal/Documents/Programming/flask-sandbox/virtual/lib/python3.8/site-packages/sqlalchemy/engine/base.py", line 3146, in _run_ddl_visitor
    with self.begin() as conn:
  File "/mnt/c/Users/bamal/Documents/Programming/flask-sandbox/virtual/lib/python3.8/site-packages/sqlalchemy/engine/base.py", line 3062, in begin
    conn = self.connect(close_with_result=close_with_result)
  File "/mnt/c/Users/bamal/Documents/Programming/flask-sandbox/virtual/lib/python3.8/site-packages/sqlalchemy/engine/base.py", line 3234, in connect
    return self._connection_cls(self, close_with_result=close_with_result)
  File "/mnt/c/Users/bamal/Documents/Programming/flask-sandbox/virtual/lib/python3.8/site-packages/sqlalchemy/engine/base.py", line 96, in __init__
    else engine.raw_connection()
  File "/mnt/c/Users/bamal/Documents/Programming/flask-sandbox/virtual/lib/python3.8/site-packages/sqlalchemy/engine/base.py", line 3313, in raw_connection
    return self._wrap_pool_connect(self.pool.connect, _connection)
  File "/mnt/c/Users/bamal/Documents/Programming/flask-sandbox/virtual/lib/python3.8/site-packages/sqlalchemy/engine/base.py", line 3283, in _wrap_pool_connect
    Connection._handle_dbapi_exception_noconnection(
  File "/mnt/c/Users/bamal/Documents/Programming/flask-sandbox/virtual/lib/python3.8/site-packages/sqlalchemy/engine/base.py", line 2117, in _handle_dbapi_exception_noconnection
    util.raise_(
  File "/mnt/c/Users/bamal/Documents/Programming/flask-sandbox/virtual/lib/python3.8/site-packages/sqlalchemy/util/compat.py", line 207, in raise_
    raise exception
  File "/mnt/c/Users/bamal/Documents/Programming/flask-sandbox/virtual/lib/python3.8/site-packages/sqlalchemy/engine/base.py", line 3280, in _wrap_pool_connect
    return fn()
  File "/mnt/c/Users/bamal/Documents/Programming/flask-sandbox/virtual/lib/python3.8/site-packages/sqlalchemy/pool/base.py", line 310, in connect
    return _ConnectionFairy._checkout(self)
  File "/mnt/c/Users/bamal/Documents/Programming/flask-sandbox/virtual/lib/python3.8/site-packages/sqlalchemy/pool/base.py", line 868, in _checkout
    fairy = _ConnectionRecord.checkout(pool)
  File "/mnt/c/Users/bamal/Documents/Programming/flask-sandbox/virtual/lib/python3.8/site-packages/sqlalchemy/pool/base.py", line 476, in checkout
    rec = pool._do_get()
  File "/mnt/c/Users/bamal/Documents/Programming/flask-sandbox/virtual/lib/python3.8/site-packages/sqlalchemy/pool/impl.py", line 256, in _do_get
    return self._create_connection()
  File "/mnt/c/Users/bamal/Documents/Programming/flask-sandbox/virtual/lib/python3.8/site-packages/sqlalchemy/pool/base.py", line 256, in _create_connection
    return _ConnectionRecord(self)
  File "/mnt/c/Users/bamal/Documents/Programming/flask-sandbox/virtual/lib/python3.8/site-packages/sqlalchemy/pool/base.py", line 371, in __init__
    self.__connect()
  File "/mnt/c/Users/bamal/Documents/Programming/flask-sandbox/virtual/lib/python3.8/site-packages/sqlalchemy/pool/base.py", line 666, in __connect
    pool.logger.debug("Error on connect(): %s", e)
  File "/mnt/c/Users/bamal/Documents/Programming/flask-sandbox/virtual/lib/python3.8/site-packages/sqlalchemy/util/langhelpers.py", line 70, in __exit__
    compat.raise_(
  File "/mnt/c/Users/bamal/Documents/Programming/flask-sandbox/virtual/lib/python3.8/site-packages/sqlalchemy/util/compat.py", line 207, in raise_
    raise exception
  File "/mnt/c/Users/bamal/Documents/Programming/flask-sandbox/virtual/lib/python3.8/site-packages/sqlalchemy/pool/base.py", line 661, in __connect
    self.dbapi_connection = connection = pool._invoke_creator(self)
  File "/mnt/c/Users/bamal/Documents/Programming/flask-sandbox/virtual/lib/python3.8/site-packages/sqlalchemy/engine/create.py", line 590, in connect
    return dialect.connect(*cargs, **cparams)
  File "/mnt/c/Users/bamal/Documents/Programming/flask-sandbox/virtual/lib/python3.8/site-packages/sqlalchemy/engine/default.py", line 597, in connect
    return self.dbapi.connect(*cargs, **cparams)
sqlalchemy.exc.OperationalError: (sqlite3.OperationalError) unable to open database file
(Background on this error at: https://sqlalche.me/e/14/e3q8)

======================================================================
ERROR: test_logout_view (__main__.TestViews)
Test that logout link is inaccessible without login
----------------------------------------------------------------------
Traceback (most recent call last):
  File "/mnt/c/Users/bamal/Documents/Programming/flask-sandbox/virtual/lib/python3.8/site-packages/sqlalchemy/engine/base.py", line 3280, in _wrap_pool_connect
    return fn()
  File "/mnt/c/Users/bamal/Documents/Programming/flask-sandbox/virtual/lib/python3.8/site-packages/sqlalchemy/pool/base.py", line 310, in connect
    return _ConnectionFairy._checkout(self)
  File "/mnt/c/Users/bamal/Documents/Programming/flask-sandbox/virtual/lib/python3.8/site-packages/sqlalchemy/pool/base.py", line 868, in _checkout
    fairy = _ConnectionRecord.checkout(pool)
  File "/mnt/c/Users/bamal/Documents/Programming/flask-sandbox/virtual/lib/python3.8/site-packages/sqlalchemy/pool/base.py", line 476, in checkout
    rec = pool._do_get()
  File "/mnt/c/Users/bamal/Documents/Programming/flask-sandbox/virtual/lib/python3.8/site-packages/sqlalchemy/pool/impl.py", line 256, in _do_get
    return self._create_connection()
  File "/mnt/c/Users/bamal/Documents/Programming/flask-sandbox/virtual/lib/python3.8/site-packages/sqlalchemy/pool/base.py", line 256, in _create_connection
    return _ConnectionRecord(self)
  File "/mnt/c/Users/bamal/Documents/Programming/flask-sandbox/virtual/lib/python3.8/site-packages/sqlalchemy/pool/base.py", line 371, in __init__
    self.__connect()
  File "/mnt/c/Users/bamal/Documents/Programming/flask-sandbox/virtual/lib/python3.8/site-packages/sqlalchemy/pool/base.py", line 666, in __connect
    pool.logger.debug("Error on connect(): %s", e)
  File "/mnt/c/Users/bamal/Documents/Programming/flask-sandbox/virtual/lib/python3.8/site-packages/sqlalchemy/util/langhelpers.py", line 70, in __exit__
    compat.raise_(
  File "/mnt/c/Users/bamal/Documents/Programming/flask-sandbox/virtual/lib/python3.8/site-packages/sqlalchemy/util/compat.py", line 207, in raise_
    raise exception
  File "/mnt/c/Users/bamal/Documents/Programming/flask-sandbox/virtual/lib/python3.8/site-packages/sqlalchemy/pool/base.py", line 661, in __connect
    self.dbapi_connection = connection = pool._invoke_creator(self)
  File "/mnt/c/Users/bamal/Documents/Programming/flask-sandbox/virtual/lib/python3.8/site-packages/sqlalchemy/engine/create.py", line 590, in connect
    return dialect.connect(*cargs, **cparams)
  File "/mnt/c/Users/bamal/Documents/Programming/flask-sandbox/virtual/lib/python3.8/site-packages/sqlalchemy/engine/default.py", line 597, in connect
    return self.dbapi.connect(*cargs, **cparams)
sqlite3.OperationalError: unable to open database file

The above exception was the direct cause of the following exception:

Traceback (most recent call last):
  File "/mnt/c/Users/bamal/Documents/Programming/flask-sandbox/tests.py", line 35, in setUp
    db.create_all()
  File "/mnt/c/Users/bamal/Documents/Programming/flask-sandbox/virtual/lib/python3.8/site-packages/flask_sqlalchemy/__init__.py", line 1094, in create_all
    self._execute_for_all_tables(app, bind, 'create_all')
  File "/mnt/c/Users/bamal/Documents/Programming/flask-sandbox/virtual/lib/python3.8/site-packages/flask_sqlalchemy/__init__.py", line 1086, in _execute_for_all_tables
    op(bind=self.get_engine(app, bind), **extra)
  File "/mnt/c/Users/bamal/Documents/Programming/flask-sandbox/virtual/lib/python3.8/site-packages/sqlalchemy/sql/schema.py", line 4889, in create_all
    bind._run_ddl_visitor(
  File "/mnt/c/Users/bamal/Documents/Programming/flask-sandbox/virtual/lib/python3.8/site-packages/sqlalchemy/engine/base.py", line 3146, in _run_ddl_visitor
    with self.begin() as conn:
  File "/mnt/c/Users/bamal/Documents/Programming/flask-sandbox/virtual/lib/python3.8/site-packages/sqlalchemy/engine/base.py", line 3062, in begin
    conn = self.connect(close_with_result=close_with_result)
  File "/mnt/c/Users/bamal/Documents/Programming/flask-sandbox/virtual/lib/python3.8/site-packages/sqlalchemy/engine/base.py", line 3234, in connect
    return self._connection_cls(self, close_with_result=close_with_result)
  File "/mnt/c/Users/bamal/Documents/Programming/flask-sandbox/virtual/lib/python3.8/site-packages/sqlalchemy/engine/base.py", line 96, in __init__
    else engine.raw_connection()
  File "/mnt/c/Users/bamal/Documents/Programming/flask-sandbox/virtual/lib/python3.8/site-packages/sqlalchemy/engine/base.py", line 3313, in raw_connection
    return self._wrap_pool_connect(self.pool.connect, _connection)
  File "/mnt/c/Users/bamal/Documents/Programming/flask-sandbox/virtual/lib/python3.8/site-packages/sqlalchemy/engine/base.py", line 3283, in _wrap_pool_connect
    Connection._handle_dbapi_exception_noconnection(
  File "/mnt/c/Users/bamal/Documents/Programming/flask-sandbox/virtual/lib/python3.8/site-packages/sqlalchemy/engine/base.py", line 2117, in _handle_dbapi_exception_noconnection
    util.raise_(
  File "/mnt/c/Users/bamal/Documents/Programming/flask-sandbox/virtual/lib/python3.8/site-packages/sqlalchemy/util/compat.py", line 207, in raise_
    raise exception
  File "/mnt/c/Users/bamal/Documents/Programming/flask-sandbox/virtual/lib/python3.8/site-packages/sqlalchemy/engine/base.py", line 3280, in _wrap_pool_connect
    return fn()
  File "/mnt/c/Users/bamal/Documents/Programming/flask-sandbox/virtual/lib/python3.8/site-packages/sqlalchemy/pool/base.py", line 310, in connect
    return _ConnectionFairy._checkout(self)
  File "/mnt/c/Users/bamal/Documents/Programming/flask-sandbox/virtual/lib/python3.8/site-packages/sqlalchemy/pool/base.py", line 868, in _checkout
    fairy = _ConnectionRecord.checkout(pool)
  File "/mnt/c/Users/bamal/Documents/Programming/flask-sandbox/virtual/lib/python3.8/site-packages/sqlalchemy/pool/base.py", line 476, in checkout
    rec = pool._do_get()
  File "/mnt/c/Users/bamal/Documents/Programming/flask-sandbox/virtual/lib/python3.8/site-packages/sqlalchemy/pool/impl.py", line 256, in _do_get
    return self._create_connection()
  File "/mnt/c/Users/bamal/Documents/Programming/flask-sandbox/virtual/lib/python3.8/site-packages/sqlalchemy/pool/base.py", line 256, in _create_connection
    return _ConnectionRecord(self)
  File "/mnt/c/Users/bamal/Documents/Programming/flask-sandbox/virtual/lib/python3.8/site-packages/sqlalchemy/pool/base.py", line 371, in __init__
    self.__connect()
  File "/mnt/c/Users/bamal/Documents/Programming/flask-sandbox/virtual/lib/python3.8/site-packages/sqlalchemy/pool/base.py", line 666, in __connect
    pool.logger.debug("Error on connect(): %s", e)
  File "/mnt/c/Users/bamal/Documents/Programming/flask-sandbox/virtual/lib/python3.8/site-packages/sqlalchemy/util/langhelpers.py", line 70, in __exit__
    compat.raise_(
  File "/mnt/c/Users/bamal/Documents/Programming/flask-sandbox/virtual/lib/python3.8/site-packages/sqlalchemy/util/compat.py", line 207, in raise_
    raise exception
  File "/mnt/c/Users/bamal/Documents/Programming/flask-sandbox/virtual/lib/python3.8/site-packages/sqlalchemy/pool/base.py", line 661, in __connect
    self.dbapi_connection = connection = pool._invoke_creator(self)
  File "/mnt/c/Users/bamal/Documents/Programming/flask-sandbox/virtual/lib/python3.8/site-packages/sqlalchemy/engine/create.py", line 590, in connect
    return dialect.connect(*cargs, **cparams)
  File "/mnt/c/Users/bamal/Documents/Programming/flask-sandbox/virtual/lib/python3.8/site-packages/sqlalchemy/engine/default.py", line 597, in connect
    return self.dbapi.connect(*cargs, **cparams)
sqlalchemy.exc.OperationalError: (sqlite3.OperationalError) unable to open database file
(Background on this error at: https://sqlalche.me/e/14/e3q8)

======================================================================
ERROR: test_roles_view (__main__.TestViews)
Test that roles page is inaccessible without login
----------------------------------------------------------------------
Traceback (most recent call last):
  File "/mnt/c/Users/bamal/Documents/Programming/flask-sandbox/virtual/lib/python3.8/site-packages/sqlalchemy/engine/base.py", line 3280, in _wrap_pool_connect
    return fn()
  File "/mnt/c/Users/bamal/Documents/Programming/flask-sandbox/virtual/lib/python3.8/site-packages/sqlalchemy/pool/base.py", line 310, in connect
    return _ConnectionFairy._checkout(self)
  File "/mnt/c/Users/bamal/Documents/Programming/flask-sandbox/virtual/lib/python3.8/site-packages/sqlalchemy/pool/base.py", line 868, in _checkout
    fairy = _ConnectionRecord.checkout(pool)
  File "/mnt/c/Users/bamal/Documents/Programming/flask-sandbox/virtual/lib/python3.8/site-packages/sqlalchemy/pool/base.py", line 476, in checkout
    rec = pool._do_get()
  File "/mnt/c/Users/bamal/Documents/Programming/flask-sandbox/virtual/lib/python3.8/site-packages/sqlalchemy/pool/impl.py", line 256, in _do_get
    return self._create_connection()
  File "/mnt/c/Users/bamal/Documents/Programming/flask-sandbox/virtual/lib/python3.8/site-packages/sqlalchemy/pool/base.py", line 256, in _create_connection
    return _ConnectionRecord(self)
  File "/mnt/c/Users/bamal/Documents/Programming/flask-sandbox/virtual/lib/python3.8/site-packages/sqlalchemy/pool/base.py", line 371, in __init__
    self.__connect()
  File "/mnt/c/Users/bamal/Documents/Programming/flask-sandbox/virtual/lib/python3.8/site-packages/sqlalchemy/pool/base.py", line 666, in __connect
    pool.logger.debug("Error on connect(): %s", e)
  File "/mnt/c/Users/bamal/Documents/Programming/flask-sandbox/virtual/lib/python3.8/site-packages/sqlalchemy/util/langhelpers.py", line 70, in __exit__
    compat.raise_(
  File "/mnt/c/Users/bamal/Documents/Programming/flask-sandbox/virtual/lib/python3.8/site-packages/sqlalchemy/util/compat.py", line 207, in raise_
    raise exception
  File "/mnt/c/Users/bamal/Documents/Programming/flask-sandbox/virtual/lib/python3.8/site-packages/sqlalchemy/pool/base.py", line 661, in __connect
    self.dbapi_connection = connection = pool._invoke_creator(self)
  File "/mnt/c/Users/bamal/Documents/Programming/flask-sandbox/virtual/lib/python3.8/site-packages/sqlalchemy/engine/create.py", line 590, in connect
    return dialect.connect(*cargs, **cparams)
  File "/mnt/c/Users/bamal/Documents/Programming/flask-sandbox/virtual/lib/python3.8/site-packages/sqlalchemy/engine/default.py", line 597, in connect
    return self.dbapi.connect(*cargs, **cparams)
sqlite3.OperationalError: unable to open database file

The above exception was the direct cause of the following exception:

Traceback (most recent call last):
  File "/mnt/c/Users/bamal/Documents/Programming/flask-sandbox/tests.py", line 35, in setUp
    db.create_all()
  File "/mnt/c/Users/bamal/Documents/Programming/flask-sandbox/virtual/lib/python3.8/site-packages/flask_sqlalchemy/__init__.py", line 1094, in create_all
    self._execute_for_all_tables(app, bind, 'create_all')
  File "/mnt/c/Users/bamal/Documents/Programming/flask-sandbox/virtual/lib/python3.8/site-packages/flask_sqlalchemy/__init__.py", line 1086, in _execute_for_all_tables
    op(bind=self.get_engine(app, bind), **extra)
  File "/mnt/c/Users/bamal/Documents/Programming/flask-sandbox/virtual/lib/python3.8/site-packages/sqlalchemy/sql/schema.py", line 4889, in create_all
    bind._run_ddl_visitor(
  File "/mnt/c/Users/bamal/Documents/Programming/flask-sandbox/virtual/lib/python3.8/site-packages/sqlalchemy/engine/base.py", line 3146, in _run_ddl_visitor
    with self.begin() as conn:
  File "/mnt/c/Users/bamal/Documents/Programming/flask-sandbox/virtual/lib/python3.8/site-packages/sqlalchemy/engine/base.py", line 3062, in begin
    conn = self.connect(close_with_result=close_with_result)
  File "/mnt/c/Users/bamal/Documents/Programming/flask-sandbox/virtual/lib/python3.8/site-packages/sqlalchemy/engine/base.py", line 3234, in connect
    return self._connection_cls(self, close_with_result=close_with_result)
  File "/mnt/c/Users/bamal/Documents/Programming/flask-sandbox/virtual/lib/python3.8/site-packages/sqlalchemy/engine/base.py", line 96, in __init__
    else engine.raw_connection()
  File "/mnt/c/Users/bamal/Documents/Programming/flask-sandbox/virtual/lib/python3.8/site-packages/sqlalchemy/engine/base.py", line 3313, in raw_connection
    return self._wrap_pool_connect(self.pool.connect, _connection)
  File "/mnt/c/Users/bamal/Documents/Programming/flask-sandbox/virtual/lib/python3.8/site-packages/sqlalchemy/engine/base.py", line 3283, in _wrap_pool_connect
    Connection._handle_dbapi_exception_noconnection(
  File "/mnt/c/Users/bamal/Documents/Programming/flask-sandbox/virtual/lib/python3.8/site-packages/sqlalchemy/engine/base.py", line 2117, in _handle_dbapi_exception_noconnection
    util.raise_(
  File "/mnt/c/Users/bamal/Documents/Programming/flask-sandbox/virtual/lib/python3.8/site-packages/sqlalchemy/util/compat.py", line 207, in raise_
    raise exception
  File "/mnt/c/Users/bamal/Documents/Programming/flask-sandbox/virtual/lib/python3.8/site-packages/sqlalchemy/engine/base.py", line 3280, in _wrap_pool_connect
    return fn()
  File "/mnt/c/Users/bamal/Documents/Programming/flask-sandbox/virtual/lib/python3.8/site-packages/sqlalchemy/pool/base.py", line 310, in connect
    return _ConnectionFairy._checkout(self)
  File "/mnt/c/Users/bamal/Documents/Programming/flask-sandbox/virtual/lib/python3.8/site-packages/sqlalchemy/pool/base.py", line 868, in _checkout
    fairy = _ConnectionRecord.checkout(pool)
  File "/mnt/c/Users/bamal/Documents/Programming/flask-sandbox/virtual/lib/python3.8/site-packages/sqlalchemy/pool/base.py", line 476, in checkout
    rec = pool._do_get()
  File "/mnt/c/Users/bamal/Documents/Programming/flask-sandbox/virtual/lib/python3.8/site-packages/sqlalchemy/pool/impl.py", line 256, in _do_get
    return self._create_connection()
  File "/mnt/c/Users/bamal/Documents/Programming/flask-sandbox/virtual/lib/python3.8/site-packages/sqlalchemy/pool/base.py", line 256, in _create_connection
    return _ConnectionRecord(self)
  File "/mnt/c/Users/bamal/Documents/Programming/flask-sandbox/virtual/lib/python3.8/site-packages/sqlalchemy/pool/base.py", line 371, in __init__
    self.__connect()
  File "/mnt/c/Users/bamal/Documents/Programming/flask-sandbox/virtual/lib/python3.8/site-packages/sqlalchemy/pool/base.py", line 666, in __connect
    pool.logger.debug("Error on connect(): %s", e)
  File "/mnt/c/Users/bamal/Documents/Programming/flask-sandbox/virtual/lib/python3.8/site-packages/sqlalchemy/util/langhelpers.py", line 70, in __exit__
    compat.raise_(
  File "/mnt/c/Users/bamal/Documents/Programming/flask-sandbox/virtual/lib/python3.8/site-packages/sqlalchemy/util/compat.py", line 207, in raise_
    raise exception
  File "/mnt/c/Users/bamal/Documents/Programming/flask-sandbox/virtual/lib/python3.8/site-packages/sqlalchemy/pool/base.py", line 661, in __connect
    self.dbapi_connection = connection = pool._invoke_creator(self)
  File "/mnt/c/Users/bamal/Documents/Programming/flask-sandbox/virtual/lib/python3.8/site-packages/sqlalchemy/engine/create.py", line 590, in connect
    return dialect.connect(*cargs, **cparams)
  File "/mnt/c/Users/bamal/Documents/Programming/flask-sandbox/virtual/lib/python3.8/site-packages/sqlalchemy/engine/default.py", line 597, in connect
    return self.dbapi.connect(*cargs, **cparams)
sqlalchemy.exc.OperationalError: (sqlite3.OperationalError) unable to open database file
(Background on this error at: https://sqlalche.me/e/14/e3q8)

----------------------------------------------------------------------
Ran 12 tests in 202.790s

FAILED (errors=12)
